Workbook
Name ProjName: 'Start Here'!$C$5
Name Address: 'Start Here'!$C$6
Name ProjStart: 'Start Here'!$C$7
Name TargetEnd: 'Start Here'!$C$8
Name TotalBudget: 'Start Here'!$C$9
Name TotalArea: 'Start Here'!$C$10
Name AsOfOverride: 'Start Here'!$C$11
Name Currency: 'Start Here'!$C$14
Name CustomSym: 'Start Here'!$C$15
Name TaxName: 'Start Here'!$C$16
Name AreaUnit: 'Start Here'!$C$17
Name WeekStart: 'Start Here'!$C$18
Name BudgetWarnPct: 'Start Here'!$C$19
Name ContPct: 'Start Here'!$C$24
Name AlertDays: 'Start Here'!$C$25
Name OverpayTol: 'Start Here'!$C$26
Name ContAmt: 'Start Here'!$C$31
Name WorkBudget: 'Start Here'!$C$32
Name CurSym: 'Start Here'!$C$33
Name AsOf: 'Start Here'!$C$34
Name TaxWord: 'Start Here'!$C$35
Name BudgetSum: 'Budget'!$C$38
Name CommittedTotal: 'Budget'!$I$38
Name InvoicedTotal: 'Budget'!$J$38
Name PaidTotal: 'Budget'!$K$38
Name ForecastTotal: 'Budget'!$L$38
Name PendingCO: 'Budget'!$L$40
Name IssuesOpenCost: 'Budget'!$L$41
Name RiskTotal: 'Budget'!$L$42
Name ForecastRisk: 'Budget'!$L$43
Name ContUsed: 'Budget'!$L$44
Name Cash30: 'Payments'!$AC$38
Name CashMonths: 'Payments'!$Z$41:$Z$52
Name ForecastEnd: 'Timeline'!$D$4
Name OpenHigh: 'Issues & Punch List'!$B$5
Name OpenIssues: 'Issues & Punch List'!$O$8:$O$207
Name AlertCount: 'Engine'!$Y$2
Name OverdueCount: 'Engine'!$Y$3
Name UrgentCount: 'Engine'!$Y$4

Sheet Start Here
B1: 🏠 Renovation OS Lite — Start Here
B2: What this tab does: set up your project once (yellow cells), then follow the 5 steps on the right.
B3: © 2026 Hang Nguyen — Renovation OS. Licensed to the original purchaser for personal use only. Do not share, copy, resell or redistribute.
B4: YOUR PROJECT | F4: GET STARTED IN 10 MINUTES
B5: Project name | C5: Maple Lane Renovation | D5: Shown as the Dashboard title. | F5: 1 | G5: Fill in the yellow cells on the left
B6: Property address | C6: 12 Maple Lane | D6: For your own reference. | G6: Project dates, total budget, currency, tax. Everything else calculates itself.
B7: Project start date | C7: 46083 | D7: First day of the project (design counts!). The Timeline starts here. | F7: 2 | G7: Budget tab: set a budget per category
B8: Target move-in date | C8: 46255 | D8: The date you want to live in the house again. | G8: Rename categories if you like. Aim for the total to match your working budget.
B9: ="Total budget incl. "&TaxWord&" ("&CurSym&")" | C9: 135000 | D9: Everything you can spend, including tax and your safety buffer. | F9: 3 | G9: Contractors + Payments: who you pay, and when
B10: ="Total floor area ("&AreaUnit&")" | C10: 1528 | D10: Optional — used for cost per m² / ft². | G10: Enter each contract and its payment milestones — you get a warning if you pay ahead of the work.
B11: “Today” override (optional) | C11: 46188 | D11: DEMO is frozen on this date so every feature shows data — clear this cell to use today's date. | F11: 4 | G11: Timeline: set durations and dependencies
G12: Dates, the Gantt chart and late-task alerts follow automatically.
B13: PREFERENCES | F13: 5 | G13: Every Monday open the Dashboard
B14: Currency | C14: USD $ | D14: Shown next to every amount header. Pick ‘Other’ to type your own symbol. | G14: Do the ranked actions, top to bottom. That's the whole routine.
B15: Custom currency symbol | D15: Only used when Currency = Other.
B16: Tax name | C16: Sales tax | D16: VAT, Sales tax, GST… used in labels.
B17: Area unit | C17: ft² | D17: m² or ft² for room sizes. | F17: COLOUR LEGEND
B18: Week starts on | C18: Sunday | D18: Used by This Week and the Gantt chart. | G18: Light-yellow cell = YOU TYPE HERE (or pick from the dropdown).
B19: Budget ‘attention’ band | C19: 0.05 | D19: A budget line turns 🟡 when forecast is over budget by up to this %, 🔴 above. | G19: White / grey cell = automatic. Protected so you can't break a formula.
F20: 🟢 | G20: On track — nothing to do.
F21: 🟡 | G21: Needs attention soon (within your alert window).
F22: 🔴 | G22: Urgent — overdue, over budget or at risk.
B23: ALERT SETTINGS | G23: White cells are locked and protected, so a formula can never be broken by accident. Type only in the yellow cells.
B24: Contingency (safety buffer) % | C24: 0.1 | D24: 10–15% is typical. Kept aside from your total budget.
B25: Alert window (days) | C25: 7 | D25: Things due within this many days show as 🟡 ‘this week’. | F25: YOUR TABS
B26: Overpayment tolerance % | C26: 0.1 | D26: Warn when paid % is more than this ahead of work done %. | F26: ▸ | G26: Dashboard | I26: Your renovation at a glance + ranked next actions.
F27: ▸ | G27: Budget | I27: Budget vs committed vs forecast per category.
F28: ▸ | G28: Contractors | I28: Contractors, overpayment check and communication log.
F29: ▸ | G29: Payments | I29: Payment schedule, invoices and 12-month cash flow.
B30: CALCULATED FOR YOU | F30: ▸ | G30: Timeline | I30: Tasks, dependencies and Gantt chart.
B31: ="Contingency amount ("&CurSym&")" | C31: =IF(TotalBudget="",0,TotalBudget*ContPct) | D31: Kept aside for surprises — not part of your working budget. | F31: ▸ | G31: Issues & Punch List | I31: Problems found on site and the final punch list.
B32: ="Working budget ("&CurSym&")" | C32: =IF(TotalBudget="",0,TotalBudget-ContAmt) | D32: What you plan to spend. Budget lines should add up to this.
B33: Currency symbol in use | C33: =IF(Currency="Other",IF(CustomSym="","¤",CustomSym),IFERROR(INDEX('Lists'!$Q$2:$Q$14,MATCH(Currency,'Lists'!$P$2:$P$14,0)),"¤")) | F33: ⭐ Renovation OS Pro adds: quote comparison with hidden costs, change-order impact preview, decide-by / order-by dates for materials, room cards, This Week planner, document vault and warranty tracker.
B34: Today (as used by all tabs) | C34: =IF(AsOfOverride="",TODAY(),AsOfOverride)
B35: Tax word used in labels | C35: =IF(OR(TaxName="None",TaxName=""),"tax",TaxName)
B41: LICENCE & TERMS OF USE
B42: Renovation OS © 2026 Hang Nguyen. All rights reserved.
B43: • This file is licensed, not sold, to the original purchaser for personal, non-commercial use on their own home renovation.
B44: • You may NOT share, copy, resell, redistribute, sublicense, give away or upload this file (or any modified version or part of it) to any website, marketplace, group or other person.
B45: • The formulas, structure, layout and design are the intellectual property of Hang Nguyen. Removing this notice or the sheet protection is not permitted.
...

Sheet Dashboard
B1: ="🏠 "&IF(ProjName="","My renovation",ProjName)
B2: What this tab does: your renovation at a glance — updated automatically. Nothing to type here. | I2: As of | J2: =AsOf
B3: © 2026 Hang Nguyen — Renovation OS. Licensed to the original purchaser for personal use only. Do not share, copy, resell or redistribute.
B4: ="Working budget ("&CurSym&")" | D4: ="Committed ("&CurSym&")" | F4: ="Invoiced ("&CurSym&")" | H4: ="Paid ("&CurSym&")" | J4: ="Remaining to commit ("&CurSym&")"
B5: =WorkBudget | D5: =CommittedTotal | F5: =InvoicedTotal | H5: =PaidTotal | J5: =WorkBudget-CommittedTotal
B6: ="of "&FIXED(TotalBudget,0)&" total budget" | D6: =IF(WorkBudget=0,"",ROUND(CommittedTotal/WorkBudget*100,0)&"% of working budget") | F6: =IF(CommittedTotal=0,"",ROUND(InvoicedTotal/CommittedTotal*100,0)&"% of committed") | H6: ="Cash needed next 30 days: "&FIXED(Cash30,0) | J6: ="working budget − committed"
B8: ="Forecast final cost ("&CurSym&")" | D8: ="Over / under budget ("&CurSym&")" | F8: Contingency used | H8: Project day | J8: Time elapsed
B9: =ForecastTotal | D9: =ForecastTotal-WorkBudget | F9: =ContUsed | H9: =IF(OR(ProjStart="",TargetEnd=""),"–","Day "&MAX(0,AsOf-ProjStart+1)&" of "&(TargetEnd-ProjStart+1)) | J9: =IF(OR(ProjStart="",TargetEnd=""),"–",IF(TargetEnd<=ProjStart,"–",MAX(0,MIN(1,(AsOf-ProjStart)/(TargetEnd-ProjStart)))))
B10: ="incl. risk: "&FIXED(ForecastRisk,0) | D10: =IF(ForecastTotal>WorkBudget,"▲ over working budget",IF(ForecastTotal<WorkBudget,"▼ under working budget","exactly on budget")) | F10: =REPT("█",ROUND(MIN(1,MAX(0,ContUsed))*10,0))&REPT("░",10-ROUND(MIN(1,MAX(0,ContUsed))*10,0)) | H10: =IF(TargetEnd="","set dates on Start Here",IF(TargetEnd>=AsOf,(TargetEnd-AsOf)&" days to target move-in","target date has passed")) | J10: =IF(J9="–","",REPT("█",ROUND(J9*10,0))&REPT("░",10-ROUND(J9*10,0)))
B12: Forecast move-in | D12: Open issues | F12: Overdue items | H12: Late tasks | J12: Payments due soon
B13: =IF(ForecastEnd="","–",ForecastEnd) | D13: =SUM(OpenIssues) | F13: =OverdueCount | H13: =COUNTIF('Timeline'!$Q$7:$Q$156,3) | J13: =COUNTIF('Payments'!$R$6:$R$205,1)
B14: =IF(OR(ForecastEnd="",TargetEnd=""),"",IF(ForecastEnd>TargetEnd,(ForecastEnd-TargetEnd)&" days after target",IF(ForecastEnd<TargetEnd,(TargetEnd-ForecastEnd)&" days before target","on target"))) | D14: =OpenHigh&" high severity" | F14: ="of "&AlertCount&" alerts in total" | H14: ="see Timeline" | J14: ="within "&AlertDays&" days"
B16: RENOVATION HEALTH
B17: =IF(N17=0,"🟢 ON TRACK",IF(N17=1,"🟡 NEEDS ATTENTION","🔴 ACTION REQUIRED")) | N17: =MAX(N18:N23)
B18: Budget | D18: =IF(N18=0,"🟢",IF(N18=1,"🟡","🔴")) | E18: ="Forecast "&CurSym&" "&FIXED(ForecastTotal,0)&" vs working budget "&CurSym&" "&FIXED(WorkBudget,0)&IF(N18=0," — within budget",IF(N18=1," — eating into contingency"," — above your TOTAL budget!")) | N18: =IF(ForecastTotal<=WorkBudget,0,IF(ForecastTotal<=TotalBudget,1,2))
B19: Timeline | D19: =IF(N19=0,"🟢",IF(N19=1,"🟡","🔴")) | E19: =IF(ForecastEnd="","Add a project start date and tasks",IF(O19>0,O19&" late task(s) that other tasks depend on · ","")&"forecast move-in "&IF(TargetEnd="","",IF(ForecastEnd>TargetEnd,(ForecastEnd-TargetEnd)&" days after target","on or before target"))) | N19: =IF(O19>0,2,IF(OR(ForecastEnd="",TargetEnd=""),0,IF(ForecastEnd>TargetEnd+14,2,IF(ForecastEnd>TargetEnd,1,0)))) | O19: =COUNTIFS('Timeline'!$Q$7:$Q$156,3,'Timeline'!$O$7:$O$156,">=1")
B20: Contractors & payments | D20: =IF(N20=0,"🟢",IF(N20=1,"🟡","🔴")) | E20: =O20&" overdue payment(s) · "&P20&" paying-ahead warning(s) · "&Q20&" payment(s) due within "&AlertDays&" days" | N20: =IF(OR(O20>0,P20>0),2,IF(Q20>0,1,0)) | O20: =COUNTIF('Payments'!$O$6:$O$205,"OVERDUE") | P20: =COUNTIF('Contractors'!$V$6:$V$35,2) | Q20: =COUNTIF('Payments'!$R$6:$R$205,1)
B21: Issues | D21: =IF(N21=0,"🟢",IF(N21=1,"🟡","🔴")) | E21: =OpenHigh&" open high-severity · "&SUM(OpenIssues)&" open in total" | N21: =IF(OpenHigh>0,2,IF(SUM(OpenIssues)>0,1,0))
B25: YOUR NEXT ACTIONS — ranked by urgency
B26: =IF(AlertCount=0,"🟢 Nothing needs your attention right now",IF(UrgentCount>0,"🔴 ","🟡 ")&AlertCount&IF(AlertCount=1," ACTION NEEDS"," ACTIONS NEED")&" YOUR ATTENTION") | N26: =IF(AlertCount=0,0,IF(UrgentCount>0,2,1))
B27: # | C27: Priority | D27: What to do | H27: Where | J27: Due | K27: When
B28: =IF('Engine'!L2="","",1) | C28: =IF(O28="","",IF(O28=1,"🔴 Urgent",IF(O28=2,"🟡 This week","🔵 Upcoming"))) | D28: =IF('Engine'!L2="","",'Engine'!L2) | H28: =IF('Engine'!K2="","",'Engine'!K2) | J28: =IF('Engine'!M2="","",'Engine'!M2) | K28: =IF(J28="","",IF(J28<AsOf,(AsOf-J28)&IF(AsOf-J28=1," day"," days")&" overdue",IF(J28=AsOf,"today","in "&(J28-AsOf)&IF(J28-AsOf=1," day"," days")))) | O28: ='Engine'!N2
B29: =IF('Engine'!L3="","",2) | C29: =IF(O29="","",IF(O29=1,"🔴 Urgent",IF(O29=2,"🟡 This week","🔵 Upcoming"))) | D29: =IF('Engine'!L3="","",'Engine'!L3) | H29: =IF('Engine'!K3="","",'Engine'!K3) | J29: =IF('Engine'!M3="","",'Engine'!M3) | K29: =IF(J29="","",IF(J29<AsOf,(AsOf-J29)&IF(AsOf-J29=1," day"," days")&" overdue",IF(J29=AsOf,"today","in "&(J29-AsOf)&IF(J29-AsOf=1," day"," days")))) | O29: ='Engine'!N3
B30: =IF('Engine'!L4="","",3) | C30: =IF(O30="","",IF(O30=1,"🔴 Urgent",IF(O30=2,"🟡 This week","🔵 Upcoming"))) | D30: =IF('Engine'!L4="","",'Engine'!L4) | H30: =IF('Engine'!K4="","",'Engine'!K4) | J30: =IF('Engine'!M4="","",'Engine'!M4) | K30: =IF(J30="","",IF(J30<AsOf,(AsOf-J30)&IF(AsOf-J30=1," day"," days")&" overdue",IF(J30=AsOf,"today","in "&(J30-AsOf)&IF(J30-AsOf=1," day"," days")))) | O30: ='Engine'!N4
B31: =IF('Engine'!L5="","",4) | C31: =IF(O31="","",IF(O31=1,"🔴 Urgent",IF(O31=2,"🟡 This week","🔵 Upcoming"))) | D31: =IF('Engine'!L5="","",'Engine'!L5) | H31: =IF('Engine'!K5="","",'Engine'!K5) | J31: =IF('Engine'!M5="","",'Engine'!M5) | K31: =IF(J31="","",IF(J31<AsOf,(AsOf-J31)&IF(AsOf-J31=1," day"," days")&" overdue",IF(J31=AsOf,"today","in "&(J31-AsOf)&IF(J31-AsOf=1," day"," days")))) | O31: ='Engine'!N5
B32: =IF('Engine'!L6="","",5) | C32: =IF(O32="","",IF(O32=1,"🔴 Urgent",IF(O32=2,"🟡 This week","🔵 Upcoming"))) | D32: =IF('Engine'!L6="","",'Engine'!L6) | H32: =IF('Engine'!K6="","",'Engine'!K6) | J32: =IF('Engine'!M6="","",'Engine'!M6) | K32: =IF(J32="","",IF(J32<AsOf,(AsOf-J32)&IF(AsOf-J32=1," day"," days")&" overdue",IF(J32=AsOf,"today","in "&(J32-AsOf)&IF(J32-AsOf=1," day"," days")))) | O32: ='Engine'!N6
B33: =IF('Engine'!L7="","",6) | C33: =IF(O33="","",IF(O33=1,"🔴 Urgent",IF(O33=2,"🟡 This week","🔵 Upcoming"))) | D33: =IF('Engine'!L7="","",'Engine'!L7) | H33: =IF('Engine'!K7="","",'Engine'!K7) | J33: =IF('Engine'!M7="","",'Engine'!M7) | K33: =IF(J33="","",IF(J33<AsOf,(AsOf-J33)&IF(AsOf-J33=1," day"," days")&" overdue",IF(J33=AsOf,"today","in "&(J33-AsOf)&IF(J33-AsOf=1," day"," days")))) | O33: ='Engine'!N7
B34: =IF('Engine'!L8="","",7) | C34: =IF(O34="","",IF(O34=1,"🔴 Urgent",IF(O34=2,"🟡 This week","🔵 Upcoming"))) | D34: =IF('Engine'!L8="","",'Engine'!L8) | H34: =IF('Engine'!K8="","",'Engine'!K8) | J34: =IF('Engine'!M8="","",'Engine'!M8) | K34: =IF(J34="","",IF(J34<AsOf,(AsOf-J34)&IF(AsOf-J34=1," day"," days")&" overdue",IF(J34=AsOf,"today","in "&(J34-AsOf)&IF(J34-AsOf=1," day"," days")))) | O34: ='Engine'!N8
B35: =IF('Engine'!L9="","",8) | C35: =IF(O35="","",IF(O35=1,"🔴 Urgent",IF(O35=2,"🟡 This week","🔵 Upcoming"))) | D35: =IF('Engine'!L9="","",'Engine'!L9) | H35: =IF('Engine'!K9="","",'Engine'!K9) | J35: =IF('Engine'!M9="","",'Engine'!M9) | K35: =IF(J35="","",IF(J35<AsOf,(AsOf-J35)&IF(AsOf-J35=1," day"," days")&" overdue",IF(J35=AsOf,"today","in "&(J35-AsOf)&IF(J35-AsOf=1," day"," days")))) | O35: ='Engine'!N9
B36: =IF('Engine'!L10="","",9) | C36: =IF(O36="","",IF(O36=1,"🔴 Urgent",IF(O36=2,"🟡 This week","🔵 Upcoming"))) | D36: =IF('Engine'!L10="","",'Engine'!L10) | H36: =IF('Engine'!K10="","",'Engine'!K10) | J36: =IF('Engine'!M10="","",'Engine'!M10) | K36: =IF(J36="","",IF(J36<AsOf,(AsOf-J36)&IF(AsOf-J36=1," day"," days")&" overdue",IF(J36=AsOf,"today","in "&(J36-AsOf)&IF(J36-AsOf=1," day"," days")))) | O36: ='Engine'!N10
B37: =IF('Engine'!L11="","",10) | C37: =IF(O37="","",IF(O37=1,"🔴 Urgent",IF(O37=2,"🟡 This week","🔵 Upcoming"))) | D37: =IF('Engine'!L11="","",'Engine'!L11) | H37: =IF('Engine'!K11="","",'Engine'!K11) | J37: =IF('Engine'!M11="","",'Engine'!M11) | K37: =IF(J37="","",IF(J37<AsOf,(AsOf-J37)&IF(AsOf-J37=1," day"," days")&" overdue",IF(J37=AsOf,"today","in "&(J37-AsOf)&IF(J37-AsOf=1," day"," days")))) | O37: ='Engine'!N11
B38: =IF(AlertCount>10,"+ "&(AlertCount-10)&" more — see each tab.","")
B40: CHARTS

Sheet Budget
B1: 💶 Budget
B2: What this tab does: compares your budget per category with what you have committed, invoiced and paid, and forecasts the final cost.
B3: © 2026 Hang Nguyen — Renovation OS. Licensed to the original purchaser for personal use only. Do not share, copy, resell or redistribute.
B4: ="Working budget ("&CurSym&")" | C4: =WorkBudget | E4: Sum of category budgets | G4: =BudgetSum | H4: =IF(WorkBudget=0,"",IF(ABS(BudgetSum-WorkBudget)<1,"✓ matches",IF(BudgetSum>WorkBudget,"▲ "&FIXED(BudgetSum-WorkBudget,0)&" more than working budget","▼ "&FIXED(WorkBudget-BudgetSum,0)&" not yet allocated")))
B7: Category | C7: ="Budget ("&CurSym&")" | D7: Stage | E7: ="Best quote ("&CurSym&")" | F7: ="Contracted ("&CurSym&")" | G7: ="Materials ("&CurSym&")" | H7: ="Approved changes ("&CurSym&")" | I7: ="Committed ("&CurSym&")" | J7: ="Invoiced ("&CurSym&")" | K7: ="Paid ("&CurSym&")" | L7: ="Forecast ("&CurSym&")" | M7: ="Variance ("&CurSym&")" | N7: Status | O7: lvl | P7: chart key
B8: Demolition | C8: 4000 | D8: Complete | E8: ="" | F8: =IF(B8="","",SUMIFS('Contractors'!$I$6:$I$35,'Contractors'!$D$6:$D$35,B8,'Contractors'!$L$6:$L$35,"Yes")) | G8: =0 | H8: =0 | I8: =IF(B8="","",F8+G8+H8) | J8: =IF(B8="","",SUMIFS('Payments'!$L$6:$L$205,'Payments'!$P$6:$P$205,B8)) | K8: =IF(B8="","",SUMIFS('Payments'!$N$6:$N$205,'Payments'!$P$6:$P$205,B8)) | L8: =IF(B8="","",IF(OR(D8="Estimating",D8=""),MAX(C8,E8,I8,J8),MAX(I8,J8))) | M8: =IF(B8="","",C8-L8) | N8: =IF(O8="","",IF(O8=0,"🟢 On track",IF(O8=1,"🟡 Watch","🔴 Over"))) | O8: =IF(B8="","",IF(L8<=C8,0,IF(L8<=C8*(1+BudgetWarnPct),1,2))) | P8: =IF(B8="","",IF(MAX(C8,L8)>0,MAX(C8,L8)+ROW()/100000,""))
B9: Structural | C9: 9000 | D9: Complete | E9: ="" | F9: =IF(B9="","",SUMIFS('Contractors'!$I$6:$I$35,'Contractors'!$D$6:$D$35,B9,'Contractors'!$L$6:$L$35,"Yes")) | G9: =0 | H9: =0 | I9: =IF(B9="","",F9+G9+H9) | J9: =IF(B9="","",SUMIFS('Payments'!$L$6:$L$205,'Payments'!$P$6:$P$205,B9)) | K9: =IF(B9="","",SUMIFS('Payments'!$N$6:$N$205,'Payments'!$P$6:$P$205,B9)) | L9: =IF(B9="","",IF(OR(D9="Estimating",D9=""),MAX(C9,E9,I9,J9),MAX(I9,J9))) | M9: =IF(B9="","",C9-L9) | N9: =IF(O9="","",IF(O9=0,"🟢 On track",IF(O9=1,"🟡 Watch","🔴 Over"))) | O9: =IF(B9="","",IF(L9<=C9,0,IF(L9<=C9*(1+BudgetWarnPct),1,2))) | P9: =IF(B9="","",IF(MAX(C9,L9)>0,MAX(C9,L9)+ROW()/100000,""))
B10: Plumbing | C10: 9500 | D10: Contracted | E10: ="" | F10: =IF(B10="","",SUMIFS('Contractors'!$I$6:$I$35,'Contractors'!$D$6:$D$35,B10,'Contractors'!$L$6:$L$35,"Yes")) | G10: =0 | H10: =0 | I10: =IF(B10="","",F10+G10+H10) | J10: =IF(B10="","",SUMIFS('Payments'!$L$6:$L$205,'Payments'!$P$6:$P$205,B10)) | K10: =IF(B10="","",SUMIFS('Payments'!$N$6:$N$205,'Payments'!$P$6:$P$205,B10)) | L10: =IF(B10="","",IF(OR(D10="Estimating",D10=""),MAX(C10,E10,I10,J10),MAX(I10,J10))) | M10: =IF(B10="","",C10-L10) | N10: =IF(O10="","",IF(O10=0,"🟢 On track",IF(O10=1,"🟡 Watch","🔴 Over"))) | O10: =IF(B10="","",IF(L10<=C10,0,IF(L10<=C10*(1+BudgetWarnPct),1,2))) | P10: =IF(B10="","",IF(MAX(C10,L10)>0,MAX(C10,L10)+ROW()/100000,""))
B11: Electrical | C11: 10000 | D11: Contracted | E11: ="" | F11: =IF(B11="","",SUMIFS('Contractors'!$I$6:$I$35,'Contractors'!$D$6:$D$35,B11,'Contractors'!$L$6:$L$35,"Yes")) | G11: =0 | H11: =0 | I11: =IF(B11="","",F11+G11+H11) | J11: =IF(B11="","",SUMIFS('Payments'!$L$6:$L$205,'Payments'!$P$6:$P$205,B11)) | K11: =IF(B11="","",SUMIFS('Payments'!$N$6:$N$205,'Payments'!$P$6:$P$205,B11)) | L11: =IF(B11="","",IF(OR(D11="Estimating",D11=""),MAX(C11,E11,I11,J11),MAX(I11,J11))) | M11: =IF(B11="","",C11-L11) | N11: =IF(O11="","",IF(O11=0,"🟢 On track",IF(O11=1,"🟡 Watch","🔴 Over"))) | O11: =IF(B11="","",IF(L11<=C11,0,IF(L11<=C11*(1+BudgetWarnPct),1,2))) | P11: =IF(B11="","",IF(MAX(C11,L11)>0,MAX(C11,L11)+ROW()/100000,""))
B12: HVAC | C12: 9000 | D12: Contracted | E12: ="" | F12: =IF(B12="","",SUMIFS('Contractors'!$I$6:$I$35,'Contractors'!$D$6:$D$35,B12,'Contractors'!$L$6:$L$35,"Yes")) | G12: =0 | H12: =0 | I12: =IF(B12="","",F12+G12+H12) | J12: =IF(B12="","",SUMIFS('Payments'!$L$6:$L$205,'Payments'!$P$6:$P$205,B12)) | K12: =IF(B12="","",SUMIFS('Payments'!$N$6:$N$205,'Payments'!$P$6:$P$205,B12)) | L12: =IF(B12="","",IF(OR(D12="Estimating",D12=""),MAX(C12,E12,I12,J12),MAX(I12,J12))) | M12: =IF(B12="","",C12-L12) | N12: =IF(O12="","",IF(O12=0,"🟢 On track",IF(O12=1,"🟡 Watch","🔴 Over"))) | O12: =IF(B12="","",IF(L12<=C12,0,IF(L12<=C12*(1+BudgetWarnPct),1,2))) | P12: =IF(B12="","",IF(MAX(C12,L12)>0,MAX(C12,L12)+ROW()/100000,""))
B13: Windows & doors | C13: 12000 | D13: Contracted | E13: ="" | F13: =IF(B13="","",SUMIFS('Contractors'!$I$6:$I$35,'Contractors'!$D$6:$D$35,B13,'Contractors'!$L$6:$L$35,"Yes")) | G13: =0 | H13: =0 | I13: =IF(B13="","",F13+G13+H13) | J13: =IF(B13="","",SUMIFS('Payments'!$L$6:$L$205,'Payments'!$P$6:$P$205,B13)) | K13: =IF(B13="","",SUMIFS('Payments'!$N$6:$N$205,'Payments'!$P$6:$P$205,B13)) | L13: =IF(B13="","",IF(OR(D13="Estimating",D13=""),MAX(C13,E13,I13,J13),MAX(I13,J13))) | M13: =IF(B13="","",C13-L13) | N13: =IF(O13="","",IF(O13=0,"🟢 On track",IF(O13=1,"🟡 Watch","🔴 Over"))) | O13: =IF(B13="","",IF(L13<=C13,0,IF(L13<=C13*(1+BudgetWarnPct),1,2))) | P13: =IF(B13="","",IF(MAX(C13,L13)>0,MAX(C13,L13)+ROW()/100000,""))
B14: Roofing | C14: 3000 | D14: Estimating | E14: ="" | F14: =IF(B14="","",SUMIFS('Contractors'!$I$6:$I$35,'Contractors'!$D$6:$D$35,B14,'Contractors'!$L$6:$L$35,"Yes")) | G14: =0 | H14: =0 | I14: =IF(B14="","",F14+G14+H14) | J14: =IF(B14="","",SUMIFS('Payments'!$L$6:$L$205,'Payments'!$P$6:$P$205,B14)) | K14: =IF(B14="","",SUMIFS('Payments'!$N$6:$N$205,'Payments'!$P$6:$P$205,B14)) | L14: =IF(B14="","",IF(OR(D14="Estimating",D14=""),MAX(C14,E14,I14,J14),MAX(I14,J14))) | M14: =IF(B14="","",C14-L14) | N14: =IF(O14="","",IF(O14=0,"🟢 On track",IF(O14=1,"🟡 Watch","🔴 Over"))) | O14: =IF(B14="","",IF(L14<=C14,0,IF(L14<=C14*(1+BudgetWarnPct),1,2))) | P14: =IF(B14="","",IF(MAX(C14,L14)>0,MAX(C14,L14)+ROW()/100000,""))
B15: Kitchen | C15: 20000 | D15: Contracted | E15: ="" | F15: =IF(B15="","",SUMIFS('Contractors'!$I$6:$I$35,'Contractors'!$D$6:$D$35,B15,'Contractors'!$L$6:$L$35,"Yes")) | G15: =0 | H15: =0 | I15: =IF(B15="","",F15+G15+H15) | J15: =IF(B15="","",SUMIFS('Payments'!$L$6:$L$205,'Payments'!$P$6:$P$205,B15)) | K15: =IF(B15="","",SUMIFS('Payments'!$N$6:$N$205,'Payments'!$P$6:$P$205,B15)) | L15: =IF(B15="","",IF(OR(D15="Estimating",D15=""),MAX(C15,E15,I15,J15),MAX(I15,J15))) | M15: =IF(B15="","",C15-L15) | N15: =IF(O15="","",IF(O15=0,"🟢 On track",IF(O15=1,"🟡 Watch","🔴 Over"))) | O15: =IF(B15="","",IF(L15<=C15,0,IF(L15<=C15*(1+BudgetWarnPct),1,2))) | P15: =IF(B15="","",IF(MAX(C15,L15)>0,MAX(C15,L15)+ROW()/100000,""))
B16: Bathrooms | C16: 15000 | D16: Contracted | E16: ="" | F16: =IF(B16="","",SUMIFS('Contractors'!$I$6:$I$35,'Contractors'!$D$6:$D$35,B16,'Contractors'!$L$6:$L$35,"Yes")) | G16: =0 | H16: =0 | I16: =IF(B16="","",F16+G16+H16) | J16: =IF(B16="","",SUMIFS('Payments'!$L$6:$L$205,'Payments'!$P$6:$P$205,B16)) | K16: =IF(B16="","",SUMIFS('Payments'!$N$6:$N$205,'Payments'!$P$6:$P$205,B16)) | L16: =IF(B16="","",IF(OR(D16="Estimating",D16=""),MAX(C16,E16,I16,J16),MAX(I16,J16))) | M16: =IF(B16="","",C16-L16) | N16: =IF(O16="","",IF(O16=0,"🟢 On track",IF(O16=1,"🟡 Watch","🔴 Over"))) | O16: =IF(B16="","",IF(L16<=C16,0,IF(L16<=C16*(1+BudgetWarnPct),1,2))) | P16: =IF(B16="","",IF(MAX(C16,L16)>0,MAX(C16,L16)+ROW()/100000,""))
B17: Flooring | C17: 8500 | D17: Estimating | E17: ="" | F17: =IF(B17="","",SUMIFS('Contractors'!$I$6:$I$35,'Contractors'!$D$6:$D$35,B17,'Contractors'!$L$6:$L$35,"Yes")) | G17: =0 | H17: =0 | I17: =IF(B17="","",F17+G17+H17) | J17: =IF(B17="","",SUMIFS('Payments'!$L$6:$L$205,'Payments'!$P$6:$P$205,B17)) | K17: =IF(B17="","",SUMIFS('Payments'!$N$6:$N$205,'Payments'!$P$6:$P$205,B17)) | L17: =IF(B17="","",IF(OR(D17="Estimating",D17=""),MAX(C17,E17,I17,J17),MAX(I17,J17))) | M17: =IF(B17="","",C17-L17) | N17: =IF(O17="","",IF(O17=0,"🟢 On track",IF(O17=1,"🟡 Watch","🔴 Over"))) | O17: =IF(B17="","",IF(L17<=C17,0,IF(L17<=C17*(1+BudgetWarnPct),1,2))) | P17: =IF(B17="","",IF(MAX(C17,L17)>0,MAX(C17,L17)+ROW()/100000,""))
B18: Painting | C18: 4500 | D18: Estimating | E18: ="" | F18: =IF(B18="","",SUMIFS('Contractors'!$I$6:$I$35,'Contractors'!$D$6:$D$35,B18,'Contractors'!$L$6:$L$35,"Yes")) | G18: =0 | H18: =0 | I18: =IF(B18="","",F18+G18+H18) | J18: =IF(B18="","",SUMIFS('Payments'!$L$6:$L$205,'Payments'!$P$6:$P$205,B18)) | K18: =IF(B18="","",SUMIFS('Payments'!$N$6:$N$205,'Payments'!$P$6:$P$205,B18)) | L18: =IF(B18="","",IF(OR(D18="Estimating",D18=""),MAX(C18,E18,I18,J18),MAX(I18,J18))) | M18: =IF(B18="","",C18-L18) | N18: =IF(O18="","",IF(O18=0,"🟢 On track",IF(O18=1,"🟡 Watch","🔴 Over"))) | O18: =IF(B18="","",IF(L18<=C18,0,IF(L18<=C18*(1+BudgetWarnPct),1,2))) | P18: =IF(B18="","",IF(MAX(C18,L18)>0,MAX(C18,L18)+ROW()/100000,""))
B19: Landscaping | C19: 2000 | D19: Estimating | E19: ="" | F19: =IF(B19="","",SUMIFS('Contractors'!$I$6:$I$35,'Contractors'!$D$6:$D$35,B19,'Contractors'!$L$6:$L$35,"Yes")) | G19: =0 | H19: =0 | I19: =IF(B19="","",F19+G19+H19) | J19: =IF(B19="","",SUMIFS('Payments'!$L$6:$L$205,'Payments'!$P$6:$P$205,B19)) | K19: =IF(B19="","",SUMIFS('Payments'!$N$6:$N$205,'Payments'!$P$6:$P$205,B19)) | L19: =IF(B19="","",IF(OR(D19="Estimating",D19=""),MAX(C19,E19,I19,J19),MAX(I19,J19))) | M19: =IF(B19="","",C19-L19) | N19: =IF(O19="","",IF(O19=0,"🟢 On track",IF(O19=1,"🟡 Watch","🔴 Over"))) | O19: =IF(B19="","",IF(L19<=C19,0,IF(L19<=C19*(1+BudgetWarnPct),1,2))) | P19: =IF(B19="","",IF(MAX(C19,L19)>0,MAX(C19,L19)+ROW()/100000,""))
... B25: Other | C25: 500 | D25: Estimating | E25: ="" | F25: =IF(B25="","",SUMIFS('Contractors'!$I$6:$I$35,'Contractors'!$D$6:$D$35,B25,'Contractors'!$L$6:$L$35,"Yes")) | G25: =0 | H25: =0 | I25: =IF(B25="","",F25+G25+H25) | J25: =IF(B25="","",SUMIFS('Payments'!$L$6:$L$205,'Payments'!$P$6:$P$205,B25)) | K25: =IF(B25="","",SUMIFS('Payments'!$N$6:$N$205,'Payments'!$P$6:$P$205,B25)) | L25: =IF(B25="","",IF(OR(D25="Estimating",D25=""),MAX(C25,E25,I25,J25),MAX(I25,J25))) | M25: =IF(B25="","",C25-L25) | N25: =IF(O25="","",IF(O25=0,"🟢 On track",IF(O25=1,"🟡 Watch","🔴 Over"))) | O25: =IF(B25="","",IF(L25<=C25,0,IF(L25<=C25*(1+BudgetWarnPct),1,2))) | P25: =IF(B25="","",IF(MAX(C25,L25)>0,MAX(C25,L25)+ROW()/100000,""))
E26: ="" | F26: =IF(B26="","",SUMIFS('Contractors'!$I$6:$I$35,'Contractors'!$D$6:$D$35,B26,'Contractors'!$L$6:$L$35,"Yes")) | G26: =0 | H26: =0 | I26: =IF(B26="","",F26+G26+H26) | J26: =IF(B26="","",SUMIFS('Payments'!$L$6:$L$205,'Payments'!$P$6:$P$205,B26)) | K26: =IF(B26="","",SUMIFS('Payments'!$N$6:$N$205,'Payments'!$P$6:$P$205,B26)) | L26: =IF(B26="","",IF(OR(D26="Estimating",D26=""),MAX(C26,E26,I26,J26),MAX(I26,J26))) | M26: =IF(B26="","",C26-L26) | N26: =IF(O26="","",IF(O26=0,"🟢 On track",IF(O26=1,"🟡 Watch","🔴 Over"))) | O26: =IF(B26="","",IF(L26<=C26,0,IF(L26<=C26*(1+BudgetWarnPct),1,2))) | P26: =IF(B26="","",IF(MAX(C26,L26)>0,MAX(C26,L26)+ROW()/100000,""))
E27: ="" | F27: =IF(B27="","",SUMIFS('Contractors'!$I$6:$I$35,'Contractors'!$D$6:$D$35,B27,'Contractors'!$L$6:$L$35,"Yes")) | G27: =0 | H27: =0 | I27: =IF(B27="","",F27+G27+H27) | J27: =IF(B27="","",SUMIFS('Payments'!$L$6:$L$205,'Payments'!$P$6:$P$205,B27)) | K27: =IF(B27="","",SUMIFS('Payments'!$N$6:$N$205,'Payments'!$P$6:$P$205,B27)) | L27: =IF(B27="","",IF(OR(D27="Estimating",D27=""),MAX(C27,E27,I27,J27),MAX(I27,J27))) | M27: =IF(B27="","",C27-L27) | N27: =IF(O27="","",IF(O27=0,"🟢 On track",IF(O27=1,"🟡 Watch","🔴 Over"))) | O27: =IF(B27="","",IF(L27<=C27,0,IF(L27<=C27*(1+BudgetWarnPct),1,2))) | P27: =IF(B27="","",IF(MAX(C27,L27)>0,MAX(C27,L27)+ROW()/100000,""))
E28: ="" | F28: =IF(B28="","",SUMIFS('Contractors'!$I$6:$I$35,'Contractors'!$D$6:$D$35,B28,'Contractors'!$L$6:$L$35,"Yes")) | G28: =0 | H28: =0 | I28: =IF(B28="","",F28+G28+H28) | J28: =IF(B28="","",SUMIFS('Payments'!$L$6:$L$205,'Payments'!$P$6:$P$205,B28)) | K28: =IF(B28="","",SUMIFS('Payments'!$N$6:$N$205,'Payments'!$P$6:$P$205,B28)) | L28: =IF(B28="","",IF(OR(D28="Estimating",D28=""),MAX(C28,E28,I28,J28),MAX(I28,J28))) | M28: =IF(B28="","",C28-L28) | N28: =IF(O28="","",IF(O28=0,"🟢 On track",IF(O28=1,"🟡 Watch","🔴 Over"))) | O28: =IF(B28="","",IF(L28<=C28,0,IF(L28<=C28*(1+BudgetWarnPct),1,2))) | P28: =IF(B28="","",IF(MAX(C28,L28)>0,MAX(C28,L28)+ROW()/100000,""))
E29: ="" | F29: =IF(B29="","",SUMIFS('Contractors'!$I$6:$I$35,'Contractors'!$D$6:$D$35,B29,'Contractors'!$L$6:$L$35,"Yes")) | G29: =0 | H29: =0 | I29: =IF(B29="","",F29+G29+H29) | J29: =IF(B29="","",SUMIFS('Payments'!$L$6:$L$205,'Payments'!$P$6:$P$205,B29)) | K29: =IF(B29="","",SUMIFS('Payments'!$N$6:$N$205,'Payments'!$P$6:$P$205,B29)) | L29: =IF(B29="","",IF(OR(D29="Estimating",D29=""),MAX(C29,E29,I29,J29),MAX(I29,J29))) | M29: =IF(B29="","",C29-L29) | N29: =IF(O29="","",IF(O29=0,"🟢 On track",IF(O29=1,"🟡 Watch","🔴 Over"))) | O29: =IF(B29="","",IF(L29<=C29,0,IF(L29<=C29*(1+BudgetWarnPct),1,2))) | P29: =IF(B29="","",IF(MAX(C29,L29)>0,MAX(C29,L29)+ROW()/100000,""))
E30: ="" | F30: =IF(B30="","",SUMIFS('Contractors'!$I$6:$I$35,'Contractors'!$D$6:$D$35,B30,'Contractors'!$L$6:$L$35,"Yes")) | G30: =0 | H30: =0 | I30: =IF(B30="","",F30+G30+H30) | J30: =IF(B30="","",SUMIFS('Payments'!$L$6:$L$205,'Payments'!$P$6:$P$205,B30)) | K30: =IF(B30="","",SUMIFS('Payments'!$N$6:$N$205,'Payments'!$P$6:$P$205,B30)) | L30: =IF(B30="","",IF(OR(D30="Estimating",D30=""),MAX(C30,E30,I30,J30),MAX(I30,J30))) | M30: =IF(B30="","",C30-L30) | N30: =IF(O30="","",IF(O30=0,"🟢 On track",IF(O30=1,"🟡 Watch","🔴 Over"))) | O30: =IF(B30="","",IF(L30<=C30,0,IF(L30<=C30*(1+BudgetWarnPct),1,2))) | P30: =IF(B30="","",IF(MAX(C30,L30)>0,MAX(C30,L30)+ROW()/100000,""))
E31: ="" | F31: =IF(B31="","",SUMIFS('Contractors'!$I$6:$I$35,'Contractors'!$D$6:$D$35,B31,'Contractors'!$L$6:$L$35,"Yes")) | G31: =0 | H31: =0 | I31: =IF(B31="","",F31+G31+H31) | J31: =IF(B31="","",SUMIFS('Payments'!$L$6:$L$205,'Payments'!$P$6:$P$205,B31)) | K31: =IF(B31="","",SUMIFS('Payments'!$N$6:$N$205,'Payments'!$P$6:$P$205,B31)) | L31: =IF(B31="","",IF(OR(D31="Estimating",D31=""),MAX(C31,E31,I31,J31),MAX(I31,J31))) | M31: =IF(B31="","",C31-L31) | N31: =IF(O31="","",IF(O31=0,"🟢 On track",IF(O31=1,"🟡 Watch","🔴 Over"))) | O31: =IF(B31="","",IF(L31<=C31,0,IF(L31<=C31*(1+BudgetWarnPct),1,2))) | P31: =IF(B31="","",IF(MAX(C31,L31)>0,MAX(C31,L31)+ROW()/100000,""))
E32: ="" | F32: =IF(B32="","",SUMIFS('Contractors'!$I$6:$I$35,'Contractors'!$D$6:$D$35,B32,'Contractors'!$L$6:$L$35,"Yes")) | G32: =0 | H32: =0 | I32: =IF(B32="","",F32+G32+H32) | J32: =IF(B32="","",SUMIFS('Payments'!$L$6:$L$205,'Payments'!$P$6:$P$205,B32)) | K32: =IF(B32="","",SUMIFS('Payments'!$N$6:$N$205,'Payments'!$P$6:$P$205,B32)) | L32: =IF(B32="","",IF(OR(D32="Estimating",D32=""),MAX(C32,E32,I32,J32),MAX(I32,J32))) | M32: =IF(B32="","",C32-L32) | N32: =IF(O32="","",IF(O32=0,"🟢 On track",IF(O32=1,"🟡 Watch","🔴 Over"))) | O32: =IF(B32="","",IF(L32<=C32,0,IF(L32<=C32*(1+BudgetWarnPct),1,2))) | P32: =IF(B32="","",IF(MAX(C32,L32)>0,MAX(C32,L32)+ROW()/100000,""))
E33: ="" | F33: =IF(B33="","",SUMIFS('Contractors'!$I$6:$I$35,'Contractors'!$D$6:$D$35,B33,'Contractors'!$L$6:$L$35,"Yes")) | G33: =0 | H33: =0 | I33: =IF(B33="","",F33+G33+H33) | J33: =IF(B33="","",SUMIFS('Payments'!$L$6:$L$205,'Payments'!$P$6:$P$205,B33)) | K33: =IF(B33="","",SUMIFS('Payments'!$N$6:$N$205,'Payments'!$P$6:$P$205,B33)) | L33: =IF(B33="","",IF(OR(D33="Estimating",D33=""),MAX(C33,E33,I33,J33),MAX(I33,J33))) | M33: =IF(B33="","",C33-L33) | N33: =IF(O33="","",IF(O33=0,"🟢 On track",IF(O33=1,"🟡 Watch","🔴 Over"))) | O33: =IF(B33="","",IF(L33<=C33,0,IF(L33<=C33*(1+BudgetWarnPct),1,2))) | P33: =IF(B33="","",IF(MAX(C33,L33)>0,MAX(C33,L33)+ROW()/100000,""))
E34: ="" | F34: =IF(B34="","",SUMIFS('Contractors'!$I$6:$I$35,'Contractors'!$D$6:$D$35,B34,'Contractors'!$L$6:$L$35,"Yes")) | G34: =0 | H34: =0 | I34: =IF(B34="","",F34+G34+H34) | J34: =IF(B34="","",SUMIFS('Payments'!$L$6:$L$205,'Payments'!$P$6:$P$205,B34)) | K34: =IF(B34="","",SUMIFS('Payments'!$N$6:$N$205,'Payments'!$P$6:$P$205,B34)) | L34: =IF(B34="","",IF(OR(D34="Estimating",D34=""),MAX(C34,E34,I34,J34),MAX(I34,J34))) | M34: =IF(B34="","",C34-L34) | N34: =IF(O34="","",IF(O34=0,"🟢 On track",IF(O34=1,"🟡 Watch","🔴 Over"))) | O34: =IF(B34="","",IF(L34<=C34,0,IF(L34<=C34*(1+BudgetWarnPct),1,2))) | P34: =IF(B34="","",IF(MAX(C34,L34)>0,MAX(C34,L34)+ROW()/100000,""))
E35: ="" | F35: =IF(B35="","",SUMIFS('Contractors'!$I$6:$I$35,'Contractors'!$D$6:$D$35,B35,'Contractors'!$L$6:$L$35,"Yes")) | G35: =0 | H35: =0 | I35: =IF(B35="","",F35+G35+H35) | J35: =IF(B35="","",SUMIFS('Payments'!$L$6:$L$205,'Payments'!$P$6:$P$205,B35)) | K35: =IF(B35="","",SUMIFS('Payments'!$N$6:$N$205,'Payments'!$P$6:$P$205,B35)) | L35: =IF(B35="","",IF(OR(D35="Estimating",D35=""),MAX(C35,E35,I35,J35),MAX(I35,J35))) | M35: =IF(B35="","",C35-L35) | N35: =IF(O35="","",IF(O35=0,"🟢 On track",IF(O35=1,"🟡 Watch","🔴 Over"))) | O35: =IF(B35="","",IF(L35<=C35,0,IF(L35<=C35*(1+BudgetWarnPct),1,2))) | P35: =IF(B35="","",IF(MAX(C35,L35)>0,MAX(C35,L35)+ROW()/100000,""))
E36: ="" | F36: =IF(B36="","",SUMIFS('Contractors'!$I$6:$I$35,'Contractors'!$D$6:$D$35,B36,'Contractors'!$L$6:$L$35,"Yes")) | G36: =0 | H36: =0 | I36: =IF(B36="","",F36+G36+H36) | J36: =IF(B36="","",SUMIFS('Payments'!$L$6:$L$205,'Payments'!$P$6:$P$205,B36)) | K36: =IF(B36="","",SUMIFS('Payments'!$N$6:$N$205,'Payments'!$P$6:$P$205,B36)) | L36: =IF(B36="","",IF(OR(D36="Estimating",D36=""),MAX(C36,E36,I36,J36),MAX(I36,J36))) | M36: =IF(B36="","",C36-L36) | N36: =IF(O36="","",IF(O36=0,"🟢 On track",IF(O36=1,"🟡 Watch","🔴 Over"))) | O36: =IF(B36="","",IF(L36<=C36,0,IF(L36<=C36*(1+BudgetWarnPct),1,2))) | P36: =IF(B36="","",IF(MAX(C36,L36)>0,MAX(C36,L36)+ROW()/100000,""))
E37: ="" | F37: =IF(B37="","",SUMIFS('Contractors'!$I$6:$I$35,'Contractors'!$D$6:$D$35,B37,'Contractors'!$L$6:$L$35,"Yes")) | G37: =0 | H37: =0 | I37: =IF(B37="","",F37+G37+H37) | J37: =IF(B37="","",SUMIFS('Payments'!$L$6:$L$205,'Payments'!$P$6:$P$205,B37)) | K37: =IF(B37="","",SUMIFS('Payments'!$N$6:$N$205,'Payments'!$P$6:$P$205,B37)) | L37: =IF(B37="","",IF(OR(D37="Estimating",D37=""),MAX(C37,E37,I37,J37),MAX(I37,J37))) | M37: =IF(B37="","",C37-L37) | N37: =IF(O37="","",IF(O37=0,"🟢 On track",IF(O37=1,"🟡 Watch","🔴 Over"))) | O37: =IF(B37="","",IF(L37<=C37,0,IF(L37<=C37*(1+BudgetWarnPct),1,2))) | P37: =IF(B37="","",IF(MAX(C37,L37)>0,MAX(C37,L37)+ROW()/100000,""))
B38: TOTAL | C38: =SUM(C8:C37) | F38: =SUM(F8:F37) | G38: =SUM(G8:G37) | H38: =SUM(H8:H37) | I38: =SUM(I8:I37) | J38: =SUM(J8:J37) | K38: =SUM(K8:K37) | L38: =SUM(L8:L37) | M38: =SUM(M8:M37) | N38: =IF(O38=0,"🟢 On track",IF(O38=1,"🟡 Watch","🔴 Over")) | O38: =IF(L38<=C38,0,IF(L38<=C38*(1+BudgetWarnPct),1,2))
B39: RISK — what could still come on top of the forecast
B40: Pending change orders (not approved yet) | L40: =0 | Q40: =IF(AND(WorkBudget>0,ForecastTotal>WorkBudget),AsOf,"") | R40: =IF(Q40="","",1) | S40: =IF(R40="","","Forecast is over your working budget by "&CurSym&" "&FIXED(ForecastTotal-WorkBudget,0)&" — review Budget")
B41: Estimated cost of open issues | L41: =SUM('Issues & Punch List'!$T$8:$T$207) | Q41: =IF(ContUsed>0.75,AsOf,"") | R41: =IF(Q41="","",1) | S41: =IF(R41="","","Contingency "&ROUND(ContUsed*100,0)&"% used — pause optional changes")
B42: RISK (could still be added) | L42: =L40+L41
B43: FORECAST INCL. RISK | L43: =ForecastTotal+L42
B44: Contingency used by forecast | L44: =IF(ContAmt>0,MAX(0,ForecastTotal-WorkBudget)/ContAmt,0) | M44: =REPT("█",ROUND(MIN(1,ContUsed)*10,0))&REPT("░",10-ROUND(MIN(1,ContUsed)*10,0))

Sheet Contractors
B1: 👷 Contractors
B2: What this tab does: one row per contractor — contract, paperwork, progress and a warning when you pay ahead of the work. Communication log below.
B3: © 2026 Hang Nguyen — Renovation OS. Licensed to the original purchaser for personal use only. Do not share, copy, resell or redistribute.
B5: Company | C5: Trade | D5: Budget category | E5: Main room | F5: Contact person | G5: Phone | H5: Email | I5: ="Contract value ("&CurSym&")" | J5: ="Approved changes ("&CurSym&")" | K5: ="Total contract ("&CurSym&")" | L5: Contract signed? | M5: Start | N5: Expected completion | O5: Insurance ✓ | P5: License ✓ | Q5: Warranty (years) | R5: % work complete | S5: ="Paid to date ("&CurSym&")" | T5: Paid % | U5: Overpayment check | V5: lvl | W5: due | X5: pri | Y5: text
B6: Hansen Demolition | C6: Demolition & strip-out | D6: Demolition | E6: Whole house | F6: Lars Hansen | G6: +31 6 1234 5678 | H6: lars@hansen-demo.example | I6: 3800 | J6: =0 | K6: =IF(B6="","",I6+J6) | L6: Yes | M6: 46132 | N6: 46141 | O6: Yes | P6: Yes | Q6: 1 | R6: 1 | S6: =IF(B6="","",SUMIFS('Payments'!$N$6:$N$205,'Payments'!$B$6:$B$205,B6)) | T6: =IF(OR(B6="",K6=0),"",S6/K6) | U6: =IF(V6="","",IF(V6=2,"⚠️ Paying ahead of work","✓ OK")) | V6: =IF(T6="","",IF(T6-R6>OverpayTol,2,0)) | W6: =IF(V6=2,AsOf,"") | X6: =IF(W6="","",1) | Y6: =IF(X6="","","Paying ahead of work: "&B6&" — paid "&ROUND(T6*100,0)&"%, work done "&ROUND(R6*100,0)&"%")
B7: Solid Structures Ltd | C7: Builder / structural | D7: Structural | E7: Living room | F7: Maria Costa | G7: +31 6 2345 6789 | H7: maria@solidstructures.example | I7: 10600 | J7: =0 | K7: =IF(B7="","",I7+J7) | L7: Yes | M7: 46142 | N7: 46153 | O7: Yes | P7: Yes | Q7: 10 | R7: 1 | S7: =IF(B7="","",SUMIFS('Payments'!$N$6:$N$205,'Payments'!$B$6:$B$205,B7)) | T7: =IF(OR(B7="",K7=0),"",S7/K7) | U7: =IF(V7="","",IF(V7=2,"⚠️ Paying ahead of work","✓ OK")) | V7: =IF(T7="","",IF(T7-R7>OverpayTol,2,0)) | W7: =IF(V7=2,AsOf,"") | X7: =IF(W7="","",1) | Y7: =IF(X7="","","Paying ahead of work: "&B7&" — paid "&ROUND(T7*100,0)&"%, work done "&ROUND(R7*100,0)&"%")
B8: FlowRight Plumbing | C8: Plumbing | D8: Plumbing | E8: Whole house | F8: Tom de Vries | G8: +31 6 3456 7890 | H8: tom@flowright.example | I8: 9200 | J8: =0 | K8: =IF(B8="","",I8+J8) | L8: Yes | M8: 46154 | N8: 46178 | O8: Yes | P8: Yes | Q8: 2 | R8: 0.6 | S8: =IF(B8="","",SUMIFS('Payments'!$N$6:$N$205,'Payments'!$B$6:$B$205,B8)) | T8: =IF(OR(B8="",K8=0),"",S8/K8) | U8: =IF(V8="","",IF(V8=2,"⚠️ Paying ahead of work","✓ OK")) | V8: =IF(T8="","",IF(T8-R8>OverpayTol,2,0)) | W8: =IF(V8=2,AsOf,"") | X8: =IF(W8="","",1) | Y8: =IF(X8="","","Paying ahead of work: "&B8&" — paid "&ROUND(T8*100,0)&"%, work done "&ROUND(R8*100,0)&"%")
B9: Bright Spark Electric | C9: Electrical | D9: Electrical | E9: Whole house | F9: Ahmed Karimi | G9: +31 6 4567 8901 | H9: ahmed@brightspark.example | I9: 10500 | J9: =0 | K9: =IF(B9="","",I9+J9) | L9: Yes | M9: 46154 | N9: 46188 | O9: Yes | P9: No | Q9: 2 | R9: 0.35 | S9: =IF(B9="","",SUMIFS('Payments'!$N$6:$N$205,'Payments'!$B$6:$B$205,B9)) | T9: =IF(OR(B9="",K9=0),"",S9/K9) | U9: =IF(V9="","",IF(V9=2,"⚠️ Paying ahead of work","✓ OK")) | V9: =IF(T9="","",IF(T9-R9>OverpayTol,2,0)) | W9: =IF(V9=2,AsOf,"") | X9: =IF(W9="","",1) | Y9: =IF(X9="","","Paying ahead of work: "&B9&" — paid "&ROUND(T9*100,0)&"%, work done "&ROUND(R9*100,0)&"%")
B10: ClimaHeat HVAC | C10: Heat pump & ventilation | D10: HVAC | E10: Whole house | F10: Eva Jansen | G10: +31 6 5678 9012 | H10: eva@climaheat.example | I10: 9300 | J10: =0 | K10: =IF(B10="","",I10+J10) | L10: Yes | M10: 46179 | N10: 46188 | O10: Yes | P10: Yes | Q10: 5 | R10: 0.25 | S10: =IF(B10="","",SUMIFS('Payments'!$N$6:$N$205,'Payments'!$B$6:$B$205,B10)) | T10: =IF(OR(B10="",K10=0),"",S10/K10) | U10: =IF(V10="","",IF(V10=2,"⚠️ Paying ahead of work","✓ OK")) | V10: =IF(T10="","",IF(T10-R10>OverpayTol,2,0)) | W10: =IF(V10=2,AsOf,"") | X10: =IF(W10="","",1) | Y10: =IF(X10="","","Paying ahead of work: "&B10&" — paid "&ROUND(T10*100,0)&"%, work done "&ROUND(R10*100,0)&"%")
B11: ClearView Windows | C11: Windows & doors | D11: Windows & doors | E11: Whole house | F11: Pieter Smit | G11: +31 6 6789 0123 | H11: pieter@clearview.example | I11: 12400 | J11: =0 | K11: =IF(B11="","",I11+J11) | L11: Yes | M11: 46142 | N11: 46149 | O11: Yes | P11: Yes | Q11: 10 | R11: 0.9 | S11: =IF(B11="","",SUMIFS('Payments'!$N$6:$N$205,'Payments'!$B$6:$B$205,B11)) | T11: =IF(OR(B11="",K11=0),"",S11/K11) | U11: =IF(V11="","",IF(V11=2,"⚠️ Paying ahead of work","✓ OK")) | V11: =IF(T11="","",IF(T11-R11>OverpayTol,2,0)) | W11: =IF(V11=2,AsOf,"") | X11: =IF(W11="","",1) | Y11: =IF(X11="","","Paying ahead of work: "&B11&" — paid "&ROUND(T11*100,0)&"%, work done "&ROUND(R11*100,0)&"%")
B12: Nordic Kitchens | C12: Kitchen supply & install | D12: Kitchen | E12: Kitchen | F12: Sofie Berg | G12: +31 6 7890 1234 | H12: sofie@nordickitchens.example | I12: 20300 | J12: =0 | K12: =IF(B12="","",I12+J12) | L12: Yes | M12: 46205 | N12: 46216 | O12: Yes | P12: Yes | Q12: 5 | R12: 0 | S12: =IF(B12="","",SUMIFS('Payments'!$N$6:$N$205,'Payments'!$B$6:$B$205,B12)) | T12: =IF(OR(B12="",K12=0),"",S12/K12) | U12: =IF(V12="","",IF(V12=2,"⚠️ Paying ahead of work","✓ OK")) | V12: =IF(T12="","",IF(T12-R12>OverpayTol,2,0)) | W12: =IF(V12=2,AsOf,"") | X12: =IF(W12="","",1) | Y12: =IF(X12="","","Paying ahead of work: "&B12&" — paid "&ROUND(T12*100,0)&"%, work done "&ROUND(R12*100,0)&"%")
B13: Aqua Bath Studio | C13: Bathroom fit-out | D13: Bathrooms | E13: Bathroom 1 | F13: Luca Romano | G13: +31 6 8901 2345 | H13: luca@aquabath.example | I13: 12850 | J13: =0 | K13: =IF(B13="","",I13+J13) | L13: Yes | M13: 46205 | N13: 46229 | O13: Yes | P13: Yes | Q13: 5 | R13: 0 | S13: =IF(B13="","",SUMIFS('Payments'!$N$6:$N$205,'Payments'!$B$6:$B$205,B13)) | T13: =IF(OR(B13="",K13=0),"",S13/K13) | U13: =IF(V13="","",IF(V13=2,"⚠️ Paying ahead of work","✓ OK")) | V13: =IF(T13="","",IF(T13-R13>OverpayTol,2,0)) | W13: =IF(V13=2,AsOf,"") | X13: =IF(W13="","",1) | Y13: =IF(X13="","","Paying ahead of work: "&B13&" — paid "&ROUND(T13*100,0)&"%, work done "&ROUND(R13*100,0)&"%")
B14: GreenPlan Architects | C14: Architect & permits | D14: Professional fees | E14: Whole house | F14: Nina Visser | G14: +31 6 9012 3456 | H14: nina@greenplan.example | I14: 4800 | J14: =0 | K14: =IF(B14="","",I14+J14) | L14: Yes | M14: 46083 | N14: 46248 | O14: Yes | P14: Yes | Q14: 0 | R14: 0.75 | S14: =IF(B14="","",SUMIFS('Payments'!$N$6:$N$205,'Payments'!$B$6:$B$205,B14)) | T14: =IF(OR(B14="",K14=0),"",S14/K14) | U14: =IF(V14="","",IF(V14=2,"⚠️ Paying ahead of work","✓ OK")) | V14: =IF(T14="","",IF(T14-R14>OverpayTol,2,0)) | W14: =IF(V14=2,AsOf,"") | X14: =IF(W14="","",1) | Y14: =IF(X14="","","Paying ahead of work: "&B14&" — paid "&ROUND(T14*100,0)&"%, work done "&ROUND(R14*100,0)&"%")
B15: Finish Line Painters | C15: Painting & decorating | D15: Painting | E15: Whole house | F15: Johan Bakker | G15: +31 6 0123 4567 | H15: johan@finishline.example | I15: 4700 | J15: =0 | K15: =IF(B15="","",I15+J15) | L15: No | O15: Yes | P15: Yes | Q15: 2 | R15: 0 | S15: =IF(B15="","",SUMIFS('Payments'!$N$6:$N$205,'Payments'!$B$6:$B$205,B15)) | T15: =IF(OR(B15="",K15=0),"",S15/K15) | U15: =IF(V15="","",IF(V15=2,"⚠️ Paying ahead of work","✓ OK")) | V15: =IF(T15="","",IF(T15-R15>OverpayTol,2,0)) | W15: =IF(V15=2,AsOf,"") | X15: =IF(W15="","",1) | Y15: =IF(X15="","","Paying ahead of work: "&B15&" — paid "&ROUND(T15*100,0)&"%, work done "&ROUND(R15*100,0)&"%")
B16: Oak & Plank Flooring | C16: Flooring | D16: Flooring | E16: Whole house | F16: Mila Peters | G16: +31 6 1122 3344 | H16: mila@oakplank.example | J16: =0 | K16: =IF(B16="","",I16+J16) | L16: No | O16: Yes | P16: Yes | Q16: 10 | S16: =IF(B16="","",SUMIFS('Payments'!$N$6:$N$205,'Payments'!$B$6:$B$205,B16)) | T16: =IF(OR(B16="",K16=0),"",S16/K16) | U16: =IF(V16="","",IF(V16=2,"⚠️ Paying ahead of work","✓ OK")) | V16: =IF(T16="","",IF(T16-R16>OverpayTol,2,0)) | W16: =IF(V16=2,AsOf,"") | X16: =IF(W16="","",1) | Y16: =IF(X16="","","Paying ahead of work: "&B16&" — paid "&ROUND(T16*100,0)&"%, work done "&ROUND(R16*100,0)&"%")
B17: StoneWorks | C17: Quartz worktop (supply) | D17: Kitchen | E17: Kitchen | F17: Order desk | G17: +31 20 555 0101 | H17: orders@stoneworks.example | I17: 2450 | J17: =0 | K17: =IF(B17="","",I17+J17) | L17: Yes | M17: 46174 | N17: 46199 | O17: Yes | P17: Yes | Q17: 10 | R17: 0 | S17: =IF(B17="","",SUMIFS('Payments'!$N$6:$N$205,'Payments'!$B$6:$B$205,B17)) | T17: =IF(OR(B17="",K17=0),"",S17/K17) | U17: =IF(V17="","",IF(V17=2,"⚠️ Paying ahead of work","✓ OK")) | V17: =IF(T17="","",IF(T17-R17>OverpayTol,2,0)) | W17: =IF(V17=2,AsOf,"") | X17: =IF(W17="","",1) | Y17: =IF(X17="","","Paying ahead of work: "&B17&" — paid "&ROUND(T17*100,0)&"%, work done "&ROUND(R17*100,0)&"%")
B18: ApplianceHub | C18: Kitchen appliances (supply) | D18: Appliances | E18: Kitchen | F18: Web shop | G18: +31 20 555 0102 | H18: service@appliancehub.example | I18: 3230 | J18: =0 | K18: =IF(B18="","",I18+J18) | L18: Yes | M18: 46167 | N18: 46211 | O18: Yes | P18: Yes | Q18: 2 | R18: 0.4 | S18: =IF(B18="","",SUMIFS('Payments'!$N$6:$N$205,'Payments'!$B$6:$B$205,B18)) | T18: =IF(OR(B18="",K18=0),"",S18/K18) | U18: =IF(V18="","",IF(V18=2,"⚠️ Paying ahead of work","✓ OK")) | V18: =IF(T18="","",IF(T18-R18>OverpayTol,2,0)) | W18: =IF(V18=2,AsOf,"") | X18: =IF(W18="","",1) | Y18: =IF(X18="","","Paying ahead of work: "&B18&" — paid "&ROUND(T18*100,0)&"%, work done "&ROUND(R18*100,0)&"%")
B19: BathWorld | C19: Vanity + shower enclosure (supply) | D19: Bathrooms | E19: Bathroom 1 | F19: Showroom | G19: +31 20 555 0103 | H19: sales@bathworld.example | I19: 2040 | J19: =0 | K19: =IF(B19="","",I19+J19) | L19: Yes | M19: 46162 | N19: 46203 | O19: Yes | P19: Yes | Q19: 5 | R19: 0.55 | S19: =IF(B19="","",SUMIFS('Payments'!$N$6:$N$205,'Payments'!$B$6:$B$205,B19)) | T19: =IF(OR(B19="",K19=0),"",S19/K19) | U19: =IF(V19="","",IF(V19=2,"⚠️ Paying ahead of work","✓ OK")) | V19: =IF(T19="","",IF(T19-R19>OverpayTol,2,0)) | W19: =IF(V19=2,AsOf,"") | X19: =IF(W19="","",1) | Y19: =IF(X19="","","Paying ahead of work: "&B19&" — paid "&ROUND(T19*100,0)&"%, work done "&ROUND(R19*100,0)&"%")
J20: =0 | K20: =IF(B20="","",I20+J20) | S20: =IF(B20="","",SUMIFS('Payments'!$N$6:$N$205,'Payments'!$B$6:$B$205,B20)) | T20: =IF(OR(B20="",K20=0),"",S20/K20) | U20: =IF(V20="","",IF(V20=2,"⚠️ Paying ahead of work","✓ OK")) | V20: =IF(T20="","",IF(T20-R20>OverpayTol,2,0)) | W20: =IF(V20=2,AsOf,"") | X20: =IF(W20="","",1) | Y20: =IF(X20="","","Paying ahead of work: "&B20&" — paid "&ROUND(T20*100,0)&"%, work done "&ROUND(R20*100,0)&"%")
J21: =0 | K21: =IF(B21="","",I21+J21) | S21: =IF(B21="","",SUMIFS('Payments'!$N$6:$N$205,'Payments'!$B$6:$B$205,B21)) | T21: =IF(OR(B21="",K21=0),"",S21/K21) | U21: =IF(V21="","",IF(V21=2,"⚠️ Paying ahead of work","✓ OK")) | V21: =IF(T21="","",IF(T21-R21>OverpayTol,2,0)) | W21: =IF(V21=2,AsOf,"") | X21: =IF(W21="","",1) | Y21: =IF(X21="","","Paying ahead of work: "&B21&" — paid "&ROUND(T21*100,0)&"%, work done "&ROUND(R21*100,0)&"%")
J22: =0 | K22: =IF(B22="","",I22+J22) | S22: =IF(B22="","",SUMIFS('Payments'!$N$6:$N$205,'Payments'!$B$6:$B$205,B22)) | T22: =IF(OR(B22="",K22=0),"",S22/K22) | U22: =IF(V22="","",IF(V22=2,"⚠️ Paying ahead of work","✓ OK")) | V22: =IF(T22="","",IF(T22-R22>OverpayTol,2,0)) | W22: =IF(V22=2,AsOf,"") | X22: =IF(W22="","",1) | Y22: =IF(X22="","","Paying ahead of work: "&B22&" — paid "&ROUND(T22*100,0)&"%, work done "&ROUND(R22*100,0)&"%")
J23: =0 | K23: =IF(B23="","",I23+J23) | S23: =IF(B23="","",SUMIFS('Payments'!$N$6:$N$205,'Payments'!$B$6:$B$205,B23)) | T23: =IF(OR(B23="",K23=0),"",S23/K23) | U23: =IF(V23="","",IF(V23=2,"⚠️ Paying ahead of work","✓ OK")) | V23: =IF(T23="","",IF(T23-R23>OverpayTol,2,0)) | W23: =IF(V23=2,AsOf,"") | X23: =IF(W23="","",1) | Y23: =IF(X23="","","Paying ahead of work: "&B23&" — paid "&ROUND(T23*100,0)&"%, work done "&ROUND(R23*100,0)&"%")
J24: =0 | K24: =IF(B24="","",I24+J24) | S24: =IF(B24="","",SUMIFS('Payments'!$N$6:$N$205,'Payments'!$B$6:$B$205,B24)) | T24: =IF(OR(B24="",K24=0),"",S24/K24) | U24: =IF(V24="","",IF(V24=2,"⚠️ Paying ahead of work","✓ OK")) | V24: =IF(T24="","",IF(T24-R24>OverpayTol,2,0)) | W24: =IF(V24=2,AsOf,"") | X24: =IF(W24="","",1) | Y24: =IF(X24="","","Paying ahead of work: "&B24&" — paid "&ROUND(T24*100,0)&"%, work done "&ROUND(R24*100,0)&"%")
J25: =0 | K25: =IF(B25="","",I25+J25) | S25: =IF(B25="","",SUMIFS('Payments'!$N$6:$N$205,'Payments'!$B$6:$B$205,B25)) | T25: =IF(OR(B25="",K25=0),"",S25/K25) | U25: =IF(V25="","",IF(V25=2,"⚠️ Paying ahead of work","✓ OK")) | V25: =IF(T25="","",IF(T25-R25>OverpayTol,2,0)) | W25: =IF(V25=2,AsOf,"") | X25: =IF(W25="","",1) | Y25: =IF(X25="","","Paying ahead of work: "&B25&" — paid "&ROUND(T25*100,0)&"%, work done "&ROUND(R25*100,0)&"%")
J26: =0 | K26: =IF(B26="","",I26+J26) | S26: =IF(B26="","",SUMIFS('Payments'!$N$6:$N$205,'Payments'!$B$6:$B$205,B26)) | T26: =IF(OR(B26="",K26=0),"",S26/K26) | U26: =IF(V26="","",IF(V26=2,"⚠️ Paying ahead of work","✓ OK")) | V26: =IF(T26="","",IF(T26-R26>OverpayTol,2,0)) | W26: =IF(V26=2,AsOf,"") | X26: =IF(W26="","",1) | Y26: =IF(X26="","","Paying ahead of work: "&B26&" — paid "&ROUND(T26*100,0)&"%, work done "&ROUND(R26*100,0)&"%")
J27: =0 | K27: =IF(B27="","",I27+J27) | S27: =IF(B27="","",SUMIFS('Payments'!$N$6:$N$205,'Payments'!$B$6:$B$205,B27)) | T27: =IF(OR(B27="",K27=0),"",S27/K27) | U27: =IF(V27="","",IF(V27=2,"⚠️ Paying ahead of work","✓ OK")) | V27: =IF(T27="","",IF(T27-R27>OverpayTol,2,0)) | W27: =IF(V27=2,AsOf,"") | X27: =IF(W27="","",1) | Y27: =IF(X27="","","Paying ahead of work: "&B27&" — paid "&ROUND(T27*100,0)&"%, work done "&ROUND(R27*100,0)&"%")
J28: =0 | K28: =IF(B28="","",I28+J28) | S28: =IF(B28="","",SUMIFS('Payments'!$N$6:$N$205,'Payments'!$B$6:$B$205,B28)) | T28: =IF(OR(B28="",K28=0),"",S28/K28) | U28: =IF(V28="","",IF(V28=2,"⚠️ Paying ahead of work","✓ OK")) | V28: =IF(T28="","",IF(T28-R28>OverpayTol,2,0)) | W28: =IF(V28=2,AsOf,"") | X28: =IF(W28="","",1) | Y28: =IF(X28="","","Paying ahead of work: "&B28&" — paid "&ROUND(T28*100,0)&"%, work done "&ROUND(R28*100,0)&"%")
J29: =0 | K29: =IF(B29="","",I29+J29) | S29: =IF(B29="","",SUMIFS('Payments'!$N$6:$N$205,'Payments'!$B$6:$B$205,B29)) | T29: =IF(OR(B29="",K29=0),"",S29/K29) | U29: =IF(V29="","",IF(V29=2,"⚠️ Paying ahead of work","✓ OK")) | V29: =IF(T29="","",IF(T29-R29>OverpayTol,2,0)) | W29: =IF(V29=2,AsOf,"") | X29: =IF(W29="","",1) | Y29: =IF(X29="","","Paying ahead of work: "&B29&" — paid "&ROUND(T29*100,0)&"%, work done "&ROUND(R29*100,0)&"%")
J30: =0 | K30: =IF(B30="","",I30+J30) | S30: =IF(B30="","",SUMIFS('Payments'!$N$6:$N$205,'Payments'!$B$6:$B$205,B30)) | T30: =IF(OR(B30="",K30=0),"",S30/K30) | U30: =IF(V30="","",IF(V30=2,"⚠️ Paying ahead of work","✓ OK")) | V30: =IF(T30="","",IF(T30-R30>OverpayTol,2,0)) | W30: =IF(V30=2,AsOf,"") | X30: =IF(W30="","",1) | Y30: =IF(X30="","","Paying ahead of work: "&B30&" — paid "&ROUND(T30*100,0)&"%, work done "&ROUND(R30*100,0)&"%")
J31: =0 | K31: =IF(B31="","",I31+J31) | S31: =IF(B31="","",SUMIFS('Payments'!$N$6:$N$205,'Payments'!$B$6:$B$205,B31)) | T31: =IF(OR(B31="",K31=0),"",S31/K31) | U31: =IF(V31="","",IF(V31=2,"⚠️ Paying ahead of work","✓ OK")) | V31: =IF(T31="","",IF(T31-R31>OverpayTol,2,0)) | W31: =IF(V31=2,AsOf,"") | X31: =IF(W31="","",1) | Y31: =IF(X31="","","Paying ahead of work: "&B31&" — paid "&ROUND(T31*100,0)&"%, work done "&ROUND(R31*100,0)&"%")
... J35: =0 | K35: =IF(B35="","",I35+J35) | S35: =IF(B35="","",SUMIFS('Payments'!$N$6:$N$205,'Payments'!$B$6:$B$205,B35)) | T35: =IF(OR(B35="",K35=0),"",S35/K35) | U35: =IF(V35="","",IF(V35=2,"⚠️ Paying ahead of work","✓ OK")) | V35: =IF(T35="","",IF(T35-R35>OverpayTol,2,0)) | W35: =IF(V35=2,AsOf,"") | X35: =IF(W35="","",1) | Y35: =IF(X35="","","Paying ahead of work: "&B35&" — paid "&ROUND(T35*100,0)&"%, work done "&ROUND(R35*100,0)&"%")
B38: COMMUNICATION LOG — every call, email and site conversation. Follow-ups turn into alerts.
B40: Contractor | C40: Date | D40: What was said / agreed | I40: Follow-up needed? | J40: Follow-up date | K40: Follow-up done? | W40: due | X40: pri | Y40: text
B41: Bright Spark Electric | C41: 46175 | D41: Asked for revised schedule after 1-week slip — no reply yet | I41: Yes | J41: 46183 | K41: No | W41: =IF(AND(B41<>"",I41="Yes",K41<>"Yes",J41<>""),J41,"") | X41: =IF(W41="","",IF(W41<AsOf,1,IF(W41<=AsOf+AlertDays,2,IF(W41<=AsOf+2*AlertDays,3,"")))) | Y41: =IF(X41="","","Follow up with "&B41&": "&D41)
B42: Oak & Plank Flooring | C42: 46185 | D42: Quote received; asked them to include skirting boards | I42: Yes | J42: 46191 | K42: No | W42: =IF(AND(B42<>"",I42="Yes",K42<>"Yes",J42<>""),J42,"") | X42: =IF(W42="","",IF(W42<AsOf,1,IF(W42<=AsOf+AlertDays,2,IF(W42<=AsOf+2*AlertDays,3,"")))) | Y42: =IF(X42="","","Follow up with "&B42&": "&D42)
B43: Nordic Kitchens | C43: 46170 | D43: Confirmed install start 2 July, delivery 1 July | I43: No | W43: =IF(AND(B43<>"",I43="Yes",K43<>"Yes",J43<>""),J43,"") | X43: =IF(W43="","",IF(W43<AsOf,1,IF(W43<=AsOf+AlertDays,2,IF(W43<=AsOf+2*AlertDays,3,"")))) | Y43: =IF(X43="","","Follow up with "&B43&": "&D43)
B44: FlowRight Plumbing | C44: 46182 | D44: Pipe re-routing caused delay; rough-in now late | I44: Yes | J44: 46174 | K44: Yes | W44: =IF(AND(B44<>"",I44="Yes",K44<>"Yes",J44<>""),J44,"") | X44: =IF(W44="","",IF(W44<AsOf,1,IF(W44<=AsOf+AlertDays,2,IF(W44<=AsOf+2*AlertDays,3,"")))) | Y44: =IF(X44="","","Follow up with "&B44&": "&D44)
W45: =IF(AND(B45<>"",I45="Yes",K45<>"Yes",J45<>""),J45,"") | X45: =IF(W45="","",IF(W45<AsOf,1,IF(W45<=AsOf+AlertDays,2,IF(W45<=AsOf+2*AlertDays,3,"")))) | Y45: =IF(X45="","","Follow up with "&B45&": "&D45)
W46: =IF(AND(B46<>"",I46="Yes",K46<>"Yes",J46<>""),J46,"") | X46: =IF(W46="","",IF(W46<AsOf,1,IF(W46<=AsOf+AlertDays,2,IF(W46<=AsOf+2*AlertDays,3,"")))) | Y46: =IF(X46="","","Follow up with "&B46&": "&D46)
W47: =IF(AND(B47<>"",I47="Yes",K47<>"Yes",J47<>""),J47,"") | X47: =IF(W47="","",IF(W47<AsOf,1,IF(W47<=AsOf+AlertDays,2,IF(W47<=AsOf+2*AlertDays,3,"")))) | Y47: =IF(X47="","","Follow up with "&B47&": "&D47)
...

Sheet Payments
B1: 💳 Payments
B2: What this tab does: your payment schedule, invoices and payments per contractor — plus a 12-month cash-flow forecast (right side →).
B3: © 2026 Hang Nguyen — Renovation OS. Licensed to the original purchaser for personal use only. Do not share, copy, resell or redistribute.
Z4: PER-CONTRACTOR SUMMARY
B5: Paid to (contractor / supplier) | C5: Milestone / what for | D5: Room (optional) | E5: Category (if not a contractor) | F5: % of contract | G5: ="…or fixed amount ("&CurSym&")" | H5: ="Scheduled ("&CurSym&")" | I5: Due date | J5: Invoice # | K5: Invoice date | L5: ="Invoiced ("&CurSym&")" | M5: Paid date | N5: ="Paid ("&CurSym&")" | O5: Status | P5: Category (auto) | Q5: room | R5: lvl | S5: unpaid | T5: 1/due | U5: due | V5: pri | W5: text | Z5: Contractor | AA5: ="Total contract ("&CurSym&")" | AB5: ="Invoiced ("&CurSym&")" | AC5: ="Paid ("&CurSym&")" | AD5: ="Still to pay ("&CurSym&")" | AE5: Next payment | AF5: ="Next amount ("&CurSym&")"
B6: GreenPlan Architects | C6: Design package 50% | F6: 0.5 | H6: =IF(B6="","",IF(G6<>"",G6,IF(F6<>"",F6*IFERROR(INDEX('Contractors'!$I$6:$I$35,MATCH(B6,'Contractors'!$B$6:$B$35,0)),0),""))) | I6: 46106 | J6: GP-01 | K6: 46101 | L6: 2400 | M6: 46105 | N6: 2400 | O6: =IF(B6="","",IF(M6<>"","Paid",IF(AND(I6<>"",I6<AsOf),"OVERDUE",IF(OR(K6<>"",L6<>""),"Invoiced","Scheduled")))) | P6: =IF(B6="","",IF(E6<>"",E6,IFERROR(INDEX('Contractors'!$D$6:$D$35,MATCH(B6,'Contractors'!$B$6:$B$35,0)),""))) | Q6: =IF(B6="","",IF(D6<>"",D6,IFERROR(INDEX('Contractors'!$E$6:$E$35,MATCH(B6,'Contractors'!$B$6:$B$35,0)),""))) | R6: =IF(O6="","",IF(O6="OVERDUE",2,IF(O6="Paid",0,IF(AND(I6<>"",I6<=AsOf+AlertDays),1,0)))) | S6: =IF(AND(B6<>"",M6="",I6<>""),IF(L6<>"",L6,IF(H6="",0,H6)),0) | T6: =IF(AND(B6<>"",M6="",I6<>""),1/I6,0) | U6: =IF(AND(B6<>"",M6="",I6<>""),I6,"") | V6: =IF(U6="","",IF(U6<AsOf,1,IF(U6<=AsOf+AlertDays,2,IF(U6<=AsOf+2*AlertDays,3,"")))) | W6: =IF(V6="","",IF(O6="OVERDUE","Overdue payment: ","Payment due: ")&B6&" — "&C6&" ("&CurSym&" "&FIXED(S6,0)&")") | Z6: =IF('Contractors'!B6="","",'Contractors'!B6) | AA6: =IF(Z6="","",'Contractors'!K6) | AB6: =IF(Z6="","",SUMIFS($L$6:$L$205,$B$6:$B$205,Z6)) | AC6: =IF(Z6="","",SUMIFS($N$6:$N$205,$B$6:$B$205,Z6)) | AD6: =IF(Z6="","",AA6-AC6) | AE6: =IF(Z6="","",IFERROR(1/SUMPRODUCT(MAX(($B$6:$B$205=Z6)*$T$6:$T$205)),"")) | AF6: =IF(AE6="","",SUMIFS($S$6:$S$205,$B$6:$B$205,Z6,$I$6:$I$205,AE6))
B7: City Building Dept | C7: Building permit fee | E7: Permits | G7: 1350 | H7: =IF(B7="","",IF(G7<>"",G7,IF(F7<>"",F7*IFERROR(INDEX('Contractors'!$I$6:$I$35,MATCH(B7,'Contractors'!$B$6:$B$35,0)),0),""))) | I7: 46111 | J7: PERMIT-2026-114 | K7: 46106 | L7: 1350 | M7: 46109 | N7: 1350 | O7: =IF(B7="","",IF(M7<>"","Paid",IF(AND(I7<>"",I7<AsOf),"OVERDUE",IF(OR(K7<>"",L7<>""),"Invoiced","Scheduled")))) | P7: =IF(B7="","",IF(E7<>"",E7,IFERROR(INDEX('Contractors'!$D$6:$D$35,MATCH(B7,'Contractors'!$B$6:$B$35,0)),""))) | Q7: =IF(B7="","",IF(D7<>"",D7,IFERROR(INDEX('Contractors'!$E$6:$E$35,MATCH(B7,'Contractors'!$B$6:$B$35,0)),""))) | R7: =IF(O7="","",IF(O7="OVERDUE",2,IF(O7="Paid",0,IF(AND(I7<>"",I7<=AsOf+AlertDays),1,0)))) | S7: =IF(AND(B7<>"",M7="",I7<>""),IF(L7<>"",L7,IF(H7="",0,H7)),0) | T7: =IF(AND(B7<>"",M7="",I7<>""),1/I7,0) | U7: =IF(AND(B7<>"",M7="",I7<>""),I7,"") | V7: =IF(U7="","",IF(U7<AsOf,1,IF(U7<=AsOf+AlertDays,2,IF(U7<=AsOf+2*AlertDays,3,"")))) | W7: =IF(V7="","",IF(O7="OVERDUE","Overdue payment: ","Payment due: ")&B7&" — "&C7&" ("&CurSym&" "&FIXED(S7,0)&")") | Z7: =IF('Contractors'!B7="","",'Contractors'!B7) | AA7: =IF(Z7="","",'Contractors'!K7) | AB7: =IF(Z7="","",SUMIFS($L$6:$L$205,$B$6:$B$205,Z7)) | AC7: =IF(Z7="","",SUMIFS($N$6:$N$205,$B$6:$B$205,Z7)) | AD7: =IF(Z7="","",AA7-AC7) | AE7: =IF(Z7="","",IFERROR(1/SUMPRODUCT(MAX(($B$6:$B$205=Z7)*$T$6:$T$205)),"")) | AF7: =IF(AE7="","",SUMIFS($S$6:$S$205,$B$6:$B$205,Z7,$I$6:$I$205,AE7))
B8: GreenPlan Architects | C8: Permit approved 25% | F8: 0.25 | H8: =IF(B8="","",IF(G8<>"",G8,IF(F8<>"",F8*IFERROR(INDEX('Contractors'!$I$6:$I$35,MATCH(B8,'Contractors'!$B$6:$B$35,0)),0),""))) | I8: 46134 | J8: GP-02 | K8: 46132 | L8: 1200 | M8: 46133 | N8: 1200 | O8: =IF(B8="","",IF(M8<>"","Paid",IF(AND(I8<>"",I8<AsOf),"OVERDUE",IF(OR(K8<>"",L8<>""),"Invoiced","Scheduled")))) | P8: =IF(B8="","",IF(E8<>"",E8,IFERROR(INDEX('Contractors'!$D$6:$D$35,MATCH(B8,'Contractors'!$B$6:$B$35,0)),""))) | Q8: =IF(B8="","",IF(D8<>"",D8,IFERROR(INDEX('Contractors'!$E$6:$E$35,MATCH(B8,'Contractors'!$B$6:$B$35,0)),""))) | R8: =IF(O8="","",IF(O8="OVERDUE",2,IF(O8="Paid",0,IF(AND(I8<>"",I8<=AsOf+AlertDays),1,0)))) | S8: =IF(AND(B8<>"",M8="",I8<>""),IF(L8<>"",L8,IF(H8="",0,H8)),0) | T8: =IF(AND(B8<>"",M8="",I8<>""),1/I8,0) | U8: =IF(AND(B8<>"",M8="",I8<>""),I8,"") | V8: =IF(U8="","",IF(U8<AsOf,1,IF(U8<=AsOf+AlertDays,2,IF(U8<=AsOf+2*AlertDays,3,"")))) | W8: =IF(V8="","",IF(O8="OVERDUE","Overdue payment: ","Payment due: ")&B8&" — "&C8&" ("&CurSym&" "&FIXED(S8,0)&")") | Z8: =IF('Contractors'!B8="","",'Contractors'!B8) | AA8: =IF(Z8="","",'Contractors'!K8) | AB8: =IF(Z8="","",SUMIFS($L$6:$L$205,$B$6:$B$205,Z8)) | AC8: =IF(Z8="","",SUMIFS($N$6:$N$205,$B$6:$B$205,Z8)) | AD8: =IF(Z8="","",AA8-AC8) | AE8: =IF(Z8="","",IFERROR(1/SUMPRODUCT(MAX(($B$6:$B$205=Z8)*$T$6:$T$205)),"")) | AF8: =IF(AE8="","",SUMIFS($S$6:$S$205,$B$6:$B$205,Z8,$I$6:$I$205,AE8))
B9: ClearView Windows | C9: Order 40% | F9: 0.4 | H9: =IF(B9="","",IF(G9<>"",G9,IF(F9<>"",F9*IFERROR(INDEX('Contractors'!$I$6:$I$35,MATCH(B9,'Contractors'!$B$6:$B$35,0)),0),""))) | I9: 46122 | J9: CV-311 | K9: 46118 | L9: 4960 | M9: 46121 | N9: 4960 | O9: =IF(B9="","",IF(M9<>"","Paid",IF(AND(I9<>"",I9<AsOf),"OVERDUE",IF(OR(K9<>"",L9<>""),"Invoiced","Scheduled")))) | P9: =IF(B9="","",IF(E9<>"",E9,IFERROR(INDEX('Contractors'!$D$6:$D$35,MATCH(B9,'Contractors'!$B$6:$B$35,0)),""))) | Q9: =IF(B9="","",IF(D9<>"",D9,IFERROR(INDEX('Contractors'!$E$6:$E$35,MATCH(B9,'Contractors'!$B$6:$B$35,0)),""))) | R9: =IF(O9="","",IF(O9="OVERDUE",2,IF(O9="Paid",0,IF(AND(I9<>"",I9<=AsOf+AlertDays),1,0)))) | S9: =IF(AND(B9<>"",M9="",I9<>""),IF(L9<>"",L9,IF(H9="",0,H9)),0) | T9: =IF(AND(B9<>"",M9="",I9<>""),1/I9,0) | U9: =IF(AND(B9<>"",M9="",I9<>""),I9,"") | V9: =IF(U9="","",IF(U9<AsOf,1,IF(U9<=AsOf+AlertDays,2,IF(U9<=AsOf+2*AlertDays,3,"")))) | W9: =IF(V9="","",IF(O9="OVERDUE","Overdue payment: ","Payment due: ")&B9&" — "&C9&" ("&CurSym&" "&FIXED(S9,0)&")") | Z9: =IF('Contractors'!B9="","",'Contractors'!B9) | AA9: =IF(Z9="","",'Contractors'!K9) | AB9: =IF(Z9="","",SUMIFS($L$6:$L$205,$B$6:$B$205,Z9)) | AC9: =IF(Z9="","",SUMIFS($N$6:$N$205,$B$6:$B$205,Z9)) | AD9: =IF(Z9="","",AA9-AC9) | AE9: =IF(Z9="","",IFERROR(1/SUMPRODUCT(MAX(($B$6:$B$205=Z9)*$T$6:$T$205)),"")) | AF9: =IF(AE9="","",SUMIFS($S$6:$S$205,$B$6:$B$205,Z9,$I$6:$I$205,AE9))
