Workbook
Name ProjName: 'Start Here'!$C$5
Name Address: 'Start Here'!$C$6
Name ProjStart: 'Start Here'!$C$7
Name TargetEnd: 'Start Here'!$C$8
Name TotalBudget: 'Start Here'!$C$9
Name TotalArea: 'Start Here'!$C$10
Name AsOfOverride: 'Start Here'!$C$11
Name Currency: 'Start Here'!$C$14
Name CustomSym: 'Start Here'!$C$15
Name TaxName: 'Start Here'!$C$16
Name VatRate: 'Start Here'!$C$17
Name DefInclTax: 'Start Here'!$C$18
Name AreaUnit: 'Start Here'!$C$19
Name WeekStart: 'Start Here'!$C$20
Name BudgetWarnPct: 'Start Here'!$C$21
Name ContPct: 'Start Here'!$C$24
Name AlertDays: 'Start Here'!$C$25
Name DecideBuf: 'Start Here'!$C$26
Name OrderBuf: 'Start Here'!$C$27
Name OverpayTol: 'Start Here'!$C$28
Name ContAmt: 'Start Here'!$C$31
Name WorkBudget: 'Start Here'!$C$32
Name CurSym: 'Start Here'!$C$33
Name AsOf: 'Start Here'!$C$34
Name TaxWord: 'Start Here'!$C$35
Name BudgetSum: 'Budget'!$C$58
Name CommittedTotal: 'Budget'!$I$58
Name InvoicedTotal: 'Budget'!$J$58
Name PaidTotal: 'Budget'!$K$58
Name ForecastTotal: 'Budget'!$L$58
Name PendingCO: 'Budget'!$L$60
Name IssuesOpenCost: 'Budget'!$L$61
Name RiskTotal: 'Budget'!$L$62
Name ForecastRisk: 'Budget'!$L$63
Name ContUsed: 'Budget'!$L$64
Name WPrice: 'Quotes'!$C$6
Name WTime: 'Quotes'!$D$6
Name WWar: 'Quotes'!$E$6
Name WComp: 'Quotes'!$F$6
Name WGut: 'Quotes'!$G$6
Name QBlockCat: 'Quotes'!$M$9:$M$18
Name QBlockInv: 'Quotes'!$O$9:$O$18
Name Cash30: 'Payments'!$AK$5
Name CashMonths: 'Payments'!$AH$8:$AH$19
Name ForecastEnd: 'Timeline'!$D$4
Name DecisionsWaiting: 'Selections & Orders'!$B$5
Name OrdersDue: 'Selections & Orders'!$E$5
Name OrdersLate: 'Selections & Orders'!$J$5
Name DeliveriesLate: 'Selections & Orders'!$P$5
Name OpenHigh: 'Issues & Punch List'!$B$5
Name OpenIssues: 'Issues & Punch List'!$O$8:$O$1007
Name DocsMissing: 'Vault'!$R$6:$R$1005
Name AlertCount: 'Engine'!$Y$2
Name OverdueCount: 'Engine'!$Y$3
Name UrgentCount: 'Engine'!$Y$4
Name WeekAlertCount: 'Engine'!$Y$5
Name WeekStartDate: 'This Week'!$C$4
Name WeekEndDate: 'This Week'!$C$5

Sheet Start Here
B1: 🏠 Renovation OS — Start Here
B2: What this tab does: set up your project once (yellow cells), then follow the 5 steps on the right.
B3: © 2026 Hang Nguyen — Renovation OS. Licensed to the original purchaser for personal use only. Do not share, copy, resell or redistribute.
B4: YOUR PROJECT | F4: GET STARTED IN 10 MINUTES
B5: Project name | C5: Maple Lane Renovation | D5: Shown as the Dashboard title. | F5: 1 | G5: Fill in the yellow cells on the left
B6: Property address | C6: 12 Maple Lane | D6: For your own reference. | G6: Project dates, total budget, currency, tax. Everything else calculates itself.
B7: Project start date | C7: 46083 | D7: First day of the project (design counts!). The Timeline starts here. | F7: 2 | G7: Budget tab: set a budget per category
B8: Target move-in date | C8: 46255 | D8: The date you want to live in the house again. | G8: Rename categories if you like. Aim for the total to match your working budget.
B9: ="Total budget incl. "&TaxWord&" ("&CurSym&")" | C9: 135000 | D9: Everything you can spend, including tax and your safety buffer. | F9: 3 | G9: Contractors + Quotes: add who you work with
B10: ="Total floor area ("&AreaUnit&")" | C10: 142 | D10: Optional — used for cost per m² / ft². | G10: Compare quotes side by side — the hidden-cost checklist shows the TRUE price.
B11: “Today” override (optional) | C11: 46188 | D11: DEMO is frozen on this date so every feature shows data — clear this cell to use today's date. | F11: 4 | G11: Timeline: set durations and dependencies
G12: Dates, Gantt chart and order-by dates for your materials follow automatically.
B13: PREFERENCES | F13: 5 | G13: Every Monday open Dashboard + This Week
B14: Currency | C14: EUR € | D14: Shown next to every amount header. Pick ‘Other’ to type your own symbol. | G14: Do the ranked actions. On Friday fill the Friday Review. That's the whole routine.
B15: Custom currency symbol | D15: Only used when Currency = Other.
B16: Tax name | C16: VAT | D16: VAT, Sales tax, GST… used in labels.
B17: Default tax rate | C17: 0.21 | D17: Used to add tax to quotes entered WITHOUT tax. | F17: COLOUR LEGEND
B18: Prices usually quoted incl. tax? | C18: Yes | D18: Pre-fills each quote; you can still change it per quote. | G18: Light-yellow cell = YOU TYPE HERE (or pick from the dropdown).
B19: Area unit | C19: m² | D19: m² or ft² for room sizes. | G19: White / grey cell = automatic. Protected so you can't break a formula.
B20: Week starts on | C20: Monday | D20: Used by This Week and the Gantt chart. | F20: 🟢 | G20: On track — nothing to do.
B21: Budget ‘attention’ band | C21: 0.05 | D21: A budget line turns 🟡 when forecast is over budget by up to this %, 🔴 above. | F21: 🟡 | G21: Needs attention soon (within your alert window).
F22: 🔴 | G22: Urgent — overdue, over budget or at risk.
B23: ALERT SETTINGS | G23: White cells are locked and protected, so a formula can never be broken by accident. Type only in the yellow cells.
B24: Contingency (safety buffer) % | C24: 0.1 | D24: 10–15% is typical. Kept aside from your total budget.
B25: Alert window (days) | C25: 7 | D25: Things due within this many days show as 🟡 ‘this week’. | F25: YOUR TABS
B26: Decide-before-order buffer (days) | C26: 7 | D26: Decide this many days before the order-by date. | F26: ▸ | G26: Dashboard | I26: Your renovation at a glance + ranked next actions.
B27: Order safety buffer (days) | C27: 5 | D27: Extra days between delivery and installation. | F27: ▸ | G27: This Week | I27: Monday plan and Friday review.
B28: Overpayment tolerance % | C28: 0.1 | D28: Warn when paid % is more than this ahead of work done %. | F28: ▸ | G28: Budget | I28: Budget vs committed vs forecast per category.
F29: ▸ | G29: Quotes | I29: Compare up to 4 quotes per trade, incl. hidden costs.
B30: CALCULATED FOR YOU | F30: ▸ | G30: Contractors | I30: Contractors, overpayment check and communication log.
B31: ="Contingency amount ("&CurSym&")" | C31: =IF(TotalBudget="",0,TotalBudget*ContPct) | D31: Kept aside for surprises — not part of your working budget. | F31: ▸ | G31: Payments | I31: Payment schedule, invoices and 12-month cash flow.
B32: ="Working budget ("&CurSym&")" | C32: =IF(TotalBudget="",0,TotalBudget-ContAmt) | D32: What you plan to spend. Budget lines should add up to this. | F32: ▸ | G32: Change Orders | I32: Change orders with impact preview before you approve.
B33: Currency symbol in use | C33: =IF(Currency="Other",IF(CustomSym="","¤",CustomSym),IFERROR(INDEX('Lists'!$Q$2:$Q$14,MATCH(Currency,'Lists'!$P$2:$P$14,0)),"¤")) | F33: ▸ | G33: Timeline | I33: Tasks, dependencies and Gantt chart.
B34: Today (as used by all tabs) | C34: =IF(AsOfOverride="",TODAY(),AsOfOverride) | F34: ▸ | G34: Rooms | I34: One card per room: money, progress, problems.
B35: Tax word used in labels | C35: =IF(OR(TaxName="None",TaxName=""),"tax",TaxName) | F35: ▸ | G35: Selections & Orders | I35: Decisions and orders — with decide-by and order-by dates.
F36: ▸ | G36: Issues & Punch List | I36: Problems found on site and the final punch list.
F37: ▸ | G37: Vault | I37: Links to every document and photo + what is missing.
F38: ▸ | G38: Warranty & Maintenance | I38: Warranties and home maintenance after the renovation.
B41: LICENCE & TERMS OF USE
B42: Renovation OS © 2026 Hang Nguyen. All rights reserved.
...

Sheet Dashboard
B1: ="🏠 "&IF(ProjName="","My renovation",ProjName)
B2: What this tab does: your renovation at a glance — updated automatically. Nothing to type here. | I2: As of | J2: =AsOf
B3: © 2026 Hang Nguyen — Renovation OS. Licensed to the original purchaser for personal use only. Do not share, copy, resell or redistribute.
B4: ="Working budget ("&CurSym&")" | D4: ="Committed ("&CurSym&")" | F4: ="Invoiced ("&CurSym&")" | H4: ="Paid ("&CurSym&")" | J4: ="Remaining to commit ("&CurSym&")"
B5: =WorkBudget | D5: =CommittedTotal | F5: =InvoicedTotal | H5: =PaidTotal | J5: =WorkBudget-CommittedTotal
B6: ="of "&FIXED(TotalBudget,0)&" total budget" | D6: =IF(WorkBudget=0,"",ROUND(CommittedTotal/WorkBudget*100,0)&"% of working budget") | F6: =IF(CommittedTotal=0,"",ROUND(InvoicedTotal/CommittedTotal*100,0)&"% of committed") | H6: ="Cash needed next 30 days: "&FIXED(Cash30,0) | J6: ="working budget − committed"
B8: ="Forecast final cost ("&CurSym&")" | D8: ="Over / under budget ("&CurSym&")" | F8: Contingency used | H8: Project day | J8: Time elapsed
B9: =ForecastTotal | D9: =ForecastTotal-WorkBudget | F9: =ContUsed | H9: =IF(OR(ProjStart="",TargetEnd=""),"–","Day "&MAX(0,AsOf-ProjStart+1)&" of "&(TargetEnd-ProjStart+1)) | J9: =IF(OR(ProjStart="",TargetEnd=""),"–",IF(TargetEnd<=ProjStart,"–",MAX(0,MIN(1,(AsOf-ProjStart)/(TargetEnd-ProjStart)))))
B10: ="incl. risk: "&FIXED(ForecastRisk,0) | D10: =IF(ForecastTotal>WorkBudget,"▲ over working budget",IF(ForecastTotal<WorkBudget,"▼ under working budget","exactly on budget")) | F10: =REPT("█",ROUND(MIN(1,MAX(0,ContUsed))*10,0))&REPT("░",10-ROUND(MIN(1,MAX(0,ContUsed))*10,0)) | H10: =IF(TargetEnd="","set dates on Start Here",IF(TargetEnd>=AsOf,(TargetEnd-AsOf)&" days to target move-in","target date has passed")) | J10: =IF(J9="–","",REPT("█",ROUND(J9*10,0))&REPT("░",10-ROUND(J9*10,0)))
B12: Forecast move-in | D12: Open issues | F12: Overdue items | H12: Decisions waiting | J12: Orders due
B13: =IF(ForecastEnd="","–",ForecastEnd) | D13: =SUM(OpenIssues) | F13: =OverdueCount | H13: =DecisionsWaiting | J13: =OrdersDue+OrdersLate
B14: =IF(OR(ForecastEnd="",TargetEnd=""),"",IF(ForecastEnd>TargetEnd,(ForecastEnd-TargetEnd)&" days after target",IF(ForecastEnd<TargetEnd,(TargetEnd-ForecastEnd)&" days before target","on target"))) | D14: =OpenHigh&" high severity" | F14: ="of "&AlertCount&" alerts in total" | H14: ="see Selections & Orders" | J14: =OrdersLate&" already late"
B16: RENOVATION HEALTH
B17: =IF(N17=0,"🟢 ON TRACK",IF(N17=1,"🟡 NEEDS ATTENTION","🔴 ACTION REQUIRED")) | N17: =MAX(N18:N23)
B18: Budget | D18: =IF(N18=0,"🟢",IF(N18=1,"🟡","🔴")) | E18: ="Forecast "&CurSym&" "&FIXED(ForecastTotal,0)&" vs working budget "&CurSym&" "&FIXED(WorkBudget,0)&IF(N18=0," — within budget",IF(N18=1," — eating into contingency"," — above your TOTAL budget!")) | N18: =IF(ForecastTotal<=WorkBudget,0,IF(ForecastTotal<=TotalBudget,1,2))
B19: Timeline | D19: =IF(N19=0,"🟢",IF(N19=1,"🟡","🔴")) | E19: =IF(ForecastEnd="","Add a project start date and tasks",IF(O19>0,O19&" late task(s) that other tasks depend on · ","")&"forecast move-in "&IF(TargetEnd="","",IF(ForecastEnd>TargetEnd,(ForecastEnd-TargetEnd)&" days after target","on or before target"))) | N19: =IF(O19>0,2,IF(OR(ForecastEnd="",TargetEnd=""),0,IF(ForecastEnd>TargetEnd+14,2,IF(ForecastEnd>TargetEnd,1,0)))) | O19: =COUNTIFS('Timeline'!$Q$7:$Q$1006,3,'Timeline'!$O$7:$O$1006,">=1")
B20: Contractors & payments | D20: =IF(N20=0,"🟢",IF(N20=1,"🟡","🔴")) | E20: =O20&" overdue payment(s) · "&P20&" paying-ahead warning(s) · "&Q20&" payment(s) due within "&AlertDays&" days" | N20: =IF(OR(O20>0,P20>0),2,IF(Q20>0,1,0)) | O20: =COUNTIF('Payments'!$O$6:$O$1005,"OVERDUE") | P20: =COUNTIF('Contractors'!$V$6:$V$1005,2) | Q20: =COUNTIF('Payments'!$R$6:$R$1005,1)
B21: Materials | D21: =IF(N21=0,"🟢",IF(N21=1,"🟡","🔴")) | E21: =OrdersLate&" late order(s) · "&DeliveriesLate&" delivery after install date · "&OrdersDue&" order(s) due within "&AlertDays&" days" | N21: =IF(OrdersLate+DeliveriesLate>0,2,IF(OrdersDue>0,1,0))
B22: Decisions | D22: =IF(N22=0,"🟢",IF(N22=1,"🟡","🔴")) | E22: =O22&" decision(s) past decide-by date · "&P22&" due within "&AlertDays&" days" | N22: =IF(O22>0,2,IF(P22>0,1,0)) | O22: =SUM('Selections & Orders'!$AE$8:$AE$1007) | P22: =SUM('Selections & Orders'!$AF$8:$AF$1007)
B23: Issues | D23: =IF(N23=0,"🟢",IF(N23=1,"🟡","🔴")) | E23: =OpenHigh&" open high-severity · "&SUM(OpenIssues)&" open in total" | N23: =IF(OpenHigh>0,2,IF(SUM(OpenIssues)>0,1,0))
B25: YOUR NEXT ACTIONS — ranked by urgency
B26: =IF(AlertCount=0,"🟢 Nothing needs your attention right now",IF(UrgentCount>0,"🔴 ","🟡 ")&AlertCount&IF(AlertCount=1," ACTION NEEDS"," ACTIONS NEED")&" YOUR ATTENTION") | N26: =IF(AlertCount=0,0,IF(UrgentCount>0,2,1))
B27: # | C27: Priority | D27: What to do | H27: Where | J27: Due | K27: When
B28: =IF('Engine'!L2="","",1) | C28: =IF(O28="","",IF(O28=1,"🔴 Urgent",IF(O28=2,"🟡 This week","🔵 Upcoming"))) | D28: =IF('Engine'!L2="","",'Engine'!L2) | H28: =IF('Engine'!K2="","",'Engine'!K2) | J28: =IF('Engine'!M2="","",'Engine'!M2) | K28: =IF(J28="","",IF(J28<AsOf,(AsOf-J28)&IF(AsOf-J28=1," day"," days")&" overdue",IF(J28=AsOf,"today","in "&(J28-AsOf)&IF(J28-AsOf=1," day"," days")))) | O28: ='Engine'!N2
B29: =IF('Engine'!L3="","",2) | C29: =IF(O29="","",IF(O29=1,"🔴 Urgent",IF(O29=2,"🟡 This week","🔵 Upcoming"))) | D29: =IF('Engine'!L3="","",'Engine'!L3) | H29: =IF('Engine'!K3="","",'Engine'!K3) | J29: =IF('Engine'!M3="","",'Engine'!M3) | K29: =IF(J29="","",IF(J29<AsOf,(AsOf-J29)&IF(AsOf-J29=1," day"," days")&" overdue",IF(J29=AsOf,"today","in "&(J29-AsOf)&IF(J29-AsOf=1," day"," days")))) | O29: ='Engine'!N3
B30: =IF('Engine'!L4="","",3) | C30: =IF(O30="","",IF(O30=1,"🔴 Urgent",IF(O30=2,"🟡 This week","🔵 Upcoming"))) | D30: =IF('Engine'!L4="","",'Engine'!L4) | H30: =IF('Engine'!K4="","",'Engine'!K4) | J30: =IF('Engine'!M4="","",'Engine'!M4) | K30: =IF(J30="","",IF(J30<AsOf,(AsOf-J30)&IF(AsOf-J30=1," day"," days")&" overdue",IF(J30=AsOf,"today","in "&(J30-AsOf)&IF(J30-AsOf=1," day"," days")))) | O30: ='Engine'!N4
B31: =IF('Engine'!L5="","",4) | C31: =IF(O31="","",IF(O31=1,"🔴 Urgent",IF(O31=2,"🟡 This week","🔵 Upcoming"))) | D31: =IF('Engine'!L5="","",'Engine'!L5) | H31: =IF('Engine'!K5="","",'Engine'!K5) | J31: =IF('Engine'!M5="","",'Engine'!M5) | K31: =IF(J31="","",IF(J31<AsOf,(AsOf-J31)&IF(AsOf-J31=1," day"," days")&" overdue",IF(J31=AsOf,"today","in "&(J31-AsOf)&IF(J31-AsOf=1," day"," days")))) | O31: ='Engine'!N5
B32: =IF('Engine'!L6="","",5) | C32: =IF(O32="","",IF(O32=1,"🔴 Urgent",IF(O32=2,"🟡 This week","🔵 Upcoming"))) | D32: =IF('Engine'!L6="","",'Engine'!L6) | H32: =IF('Engine'!K6="","",'Engine'!K6) | J32: =IF('Engine'!M6="","",'Engine'!M6) | K32: =IF(J32="","",IF(J32<AsOf,(AsOf-J32)&IF(AsOf-J32=1," day"," days")&" overdue",IF(J32=AsOf,"today","in "&(J32-AsOf)&IF(J32-AsOf=1," day"," days")))) | O32: ='Engine'!N6
B33: =IF('Engine'!L7="","",6) | C33: =IF(O33="","",IF(O33=1,"🔴 Urgent",IF(O33=2,"🟡 This week","🔵 Upcoming"))) | D33: =IF('Engine'!L7="","",'Engine'!L7) | H33: =IF('Engine'!K7="","",'Engine'!K7) | J33: =IF('Engine'!M7="","",'Engine'!M7) | K33: =IF(J33="","",IF(J33<AsOf,(AsOf-J33)&IF(AsOf-J33=1," day"," days")&" overdue",IF(J33=AsOf,"today","in "&(J33-AsOf)&IF(J33-AsOf=1," day"," days")))) | O33: ='Engine'!N7
B34: =IF('Engine'!L8="","",7) | C34: =IF(O34="","",IF(O34=1,"🔴 Urgent",IF(O34=2,"🟡 This week","🔵 Upcoming"))) | D34: =IF('Engine'!L8="","",'Engine'!L8) | H34: =IF('Engine'!K8="","",'Engine'!K8) | J34: =IF('Engine'!M8="","",'Engine'!M8) | K34: =IF(J34="","",IF(J34<AsOf,(AsOf-J34)&IF(AsOf-J34=1," day"," days")&" overdue",IF(J34=AsOf,"today","in "&(J34-AsOf)&IF(J34-AsOf=1," day"," days")))) | O34: ='Engine'!N8
B35: =IF('Engine'!L9="","",8) | C35: =IF(O35="","",IF(O35=1,"🔴 Urgent",IF(O35=2,"🟡 This week","🔵 Upcoming"))) | D35: =IF('Engine'!L9="","",'Engine'!L9) | H35: =IF('Engine'!K9="","",'Engine'!K9) | J35: =IF('Engine'!M9="","",'Engine'!M9) | K35: =IF(J35="","",IF(J35<AsOf,(AsOf-J35)&IF(AsOf-J35=1," day"," days")&" overdue",IF(J35=AsOf,"today","in "&(J35-AsOf)&IF(J35-AsOf=1," day"," days")))) | O35: ='Engine'!N9
B36: =IF('Engine'!L10="","",9) | C36: =IF(O36="","",IF(O36=1,"🔴 Urgent",IF(O36=2,"🟡 This week","🔵 Upcoming"))) | D36: =IF('Engine'!L10="","",'Engine'!L10) | H36: =IF('Engine'!K10="","",'Engine'!K10) | J36: =IF('Engine'!M10="","",'Engine'!M10) | K36: =IF(J36="","",IF(J36<AsOf,(AsOf-J36)&IF(AsOf-J36=1," day"," days")&" overdue",IF(J36=AsOf,"today","in "&(J36-AsOf)&IF(J36-AsOf=1," day"," days")))) | O36: ='Engine'!N10
B37: =IF('Engine'!L11="","",10) | C37: =IF(O37="","",IF(O37=1,"🔴 Urgent",IF(O37=2,"🟡 This week","🔵 Upcoming"))) | D37: =IF('Engine'!L11="","",'Engine'!L11) | H37: =IF('Engine'!K11="","",'Engine'!K11) | J37: =IF('Engine'!M11="","",'Engine'!M11) | K37: =IF(J37="","",IF(J37<AsOf,(AsOf-J37)&IF(AsOf-J37=1," day"," days")&" overdue",IF(J37=AsOf,"today","in "&(J37-AsOf)&IF(J37-AsOf=1," day"," days")))) | O37: ='Engine'!N11
B38: =IF(AlertCount>10,"+ "&(AlertCount-10)&" more — see This Week and in each tab.","")
B40: CHARTS

Sheet This Week
B1: 🗓️ This Week
B2: What this tab does: Monday — see everything that falls in this week. Friday — review what happened and write down next week's top 3.
B3: © 2026 Hang Nguyen — Renovation OS. Licensed to the original purchaser for personal use only. Do not share, copy, resell or redistribute.
B4: Week starting | C4: =AsOf-IF(WeekStart="Sunday",WEEKDAY(AsOf,1)-1,WEEKDAY(AsOf,3)) | D4: Tip: overwrite the yellow date to look at another week.
B5: Week ending | C5: =C4+6
B7: 📋 MONDAY PLAN — what falls in this week
B8: Decisions to make | C8: =COUNTIFS('Selections & Orders'!$T$8:$T$1007,">="&WeekStartDate,'Selections & Orders'!$T$8:$T$1007,"<="&WeekEndDate,'Selections & Orders'!$AD$8:$AD$1007,1) | D8: Selections with a decide-by date this week
B9: Orders to place | C9: =COUNTIFS('Selections & Orders'!$S$8:$S$1007,">="&WeekStartDate,'Selections & Orders'!$S$8:$S$1007,"<="&WeekEndDate,'Selections & Orders'!$AI$8:$AI$1007,1) | D9: Chosen items with an order-by date this week
B10: Payments due | C10: =COUNTIFS('Payments'!$I$6:$I$1005,">="&WeekStartDate,'Payments'!$I$6:$I$1005,"<="&WeekEndDate,'Payments'!$S$6:$S$1005,">0") | D10: Unpaid payments with a due date this week
B11: Deliveries expected | C11: =COUNTIFS('Selections & Orders'!$W$8:$W$1007,">="&WeekStartDate,'Selections & Orders'!$W$8:$W$1007,"<="&WeekEndDate,'Selections & Orders'!$X$8:$X$1007,"<>Yes") | D11: Orders arriving this week — someone must be on site
B12: Tasks starting | C12: =COUNTIFS('Timeline'!$J$7:$J$1006,">="&WeekStartDate,'Timeline'!$J$7:$J$1006,"<="&WeekEndDate) | D12: Timeline tasks starting
B13: Tasks finishing | C13: =COUNTIFS('Timeline'!$L$7:$L$1006,">="&WeekStartDate,'Timeline'!$L$7:$L$1006,"<="&WeekEndDate) | D13: Timeline tasks due to finish
B14: Issues with an action this week | C14: =COUNTIFS('Issues & Punch List'!$K$8:$K$1007,">="&WeekStartDate,'Issues & Punch List'!$K$8:$K$1007,"<="&WeekEndDate,'Issues & Punch List'!$O$8:$O$1007,1) | D14: ="Open issues in total: "&SUM(OpenIssues)
B16: 🔴 TOP 10 ALERTS DUE BY THE END OF THIS WEEK (incl. overdue)
B17: Priority | C17: Due | D17: What to do | E17: Where | F17: When
B18: =IF(I18="","",IF(I18=1,"🔴 Urgent",IF(I18=2,"🟡 This week","🔵 Upcoming"))) | C18: =IF('Engine'!U2="","",'Engine'!U2) | D18: =IF('Engine'!T2="","",'Engine'!T2) | E18: =IF('Engine'!S2="","",'Engine'!S2) | F18: =IF(C18="","",IF(C18<AsOf,(AsOf-C18)&IF(AsOf-C18=1," day"," days")&" overdue",IF(C18=AsOf,"today","in "&(C18-AsOf)&IF(C18-AsOf=1," day"," days")))) | I18: ='Engine'!V2
B19: =IF(I19="","",IF(I19=1,"🔴 Urgent",IF(I19=2,"🟡 This week","🔵 Upcoming"))) | C19: =IF('Engine'!U3="","",'Engine'!U3) | D19: =IF('Engine'!T3="","",'Engine'!T3) | E19: =IF('Engine'!S3="","",'Engine'!S3) | F19: =IF(C19="","",IF(C19<AsOf,(AsOf-C19)&IF(AsOf-C19=1," day"," days")&" overdue",IF(C19=AsOf,"today","in "&(C19-AsOf)&IF(C19-AsOf=1," day"," days")))) | I19: ='Engine'!V3
B20: =IF(I20="","",IF(I20=1,"🔴 Urgent",IF(I20=2,"🟡 This week","🔵 Upcoming"))) | C20: =IF('Engine'!U4="","",'Engine'!U4) | D20: =IF('Engine'!T4="","",'Engine'!T4) | E20: =IF('Engine'!S4="","",'Engine'!S4) | F20: =IF(C20="","",IF(C20<AsOf,(AsOf-C20)&IF(AsOf-C20=1," day"," days")&" overdue",IF(C20=AsOf,"today","in "&(C20-AsOf)&IF(C20-AsOf=1," day"," days")))) | I20: ='Engine'!V4
B21: =IF(I21="","",IF(I21=1,"🔴 Urgent",IF(I21=2,"🟡 This week","🔵 Upcoming"))) | C21: =IF('Engine'!U5="","",'Engine'!U5) | D21: =IF('Engine'!T5="","",'Engine'!T5) | E21: =IF('Engine'!S5="","",'Engine'!S5) | F21: =IF(C21="","",IF(C21<AsOf,(AsOf-C21)&IF(AsOf-C21=1," day"," days")&" overdue",IF(C21=AsOf,"today","in "&(C21-AsOf)&IF(C21-AsOf=1," day"," days")))) | I21: ='Engine'!V5
B22: =IF(I22="","",IF(I22=1,"🔴 Urgent",IF(I22=2,"🟡 This week","🔵 Upcoming"))) | C22: =IF('Engine'!U6="","",'Engine'!U6) | D22: =IF('Engine'!T6="","",'Engine'!T6) | E22: =IF('Engine'!S6="","",'Engine'!S6) | F22: =IF(C22="","",IF(C22<AsOf,(AsOf-C22)&IF(AsOf-C22=1," day"," days")&" overdue",IF(C22=AsOf,"today","in "&(C22-AsOf)&IF(C22-AsOf=1," day"," days")))) | I22: ='Engine'!V6
B23: =IF(I23="","",IF(I23=1,"🔴 Urgent",IF(I23=2,"🟡 This week","🔵 Upcoming"))) | C23: =IF('Engine'!U7="","",'Engine'!U7) | D23: =IF('Engine'!T7="","",'Engine'!T7) | E23: =IF('Engine'!S7="","",'Engine'!S7) | F23: =IF(C23="","",IF(C23<AsOf,(AsOf-C23)&IF(AsOf-C23=1," day"," days")&" overdue",IF(C23=AsOf,"today","in "&(C23-AsOf)&IF(C23-AsOf=1," day"," days")))) | I23: ='Engine'!V7
B24: =IF(I24="","",IF(I24=1,"🔴 Urgent",IF(I24=2,"🟡 This week","🔵 Upcoming"))) | C24: =IF('Engine'!U8="","",'Engine'!U8) | D24: =IF('Engine'!T8="","",'Engine'!T8) | E24: =IF('Engine'!S8="","",'Engine'!S8) | F24: =IF(C24="","",IF(C24<AsOf,(AsOf-C24)&IF(AsOf-C24=1," day"," days")&" overdue",IF(C24=AsOf,"today","in "&(C24-AsOf)&IF(C24-AsOf=1," day"," days")))) | I24: ='Engine'!V8
B25: =IF(I25="","",IF(I25=1,"🔴 Urgent",IF(I25=2,"🟡 This week","🔵 Upcoming"))) | C25: =IF('Engine'!U9="","",'Engine'!U9) | D25: =IF('Engine'!T9="","",'Engine'!T9) | E25: =IF('Engine'!S9="","",'Engine'!S9) | F25: =IF(C25="","",IF(C25<AsOf,(AsOf-C25)&IF(AsOf-C25=1," day"," days")&" overdue",IF(C25=AsOf,"today","in "&(C25-AsOf)&IF(C25-AsOf=1," day"," days")))) | I25: ='Engine'!V9
B26: =IF(I26="","",IF(I26=1,"🔴 Urgent",IF(I26=2,"🟡 This week","🔵 Upcoming"))) | C26: =IF('Engine'!U10="","",'Engine'!U10) | D26: =IF('Engine'!T10="","",'Engine'!T10) | E26: =IF('Engine'!S10="","",'Engine'!S10) | F26: =IF(C26="","",IF(C26<AsOf,(AsOf-C26)&IF(AsOf-C26=1," day"," days")&" overdue",IF(C26=AsOf,"today","in "&(C26-AsOf)&IF(C26-AsOf=1," day"," days")))) | I26: ='Engine'!V10
B27: =IF(I27="","",IF(I27=1,"🔴 Urgent",IF(I27=2,"🟡 This week","🔵 Upcoming"))) | C27: =IF('Engine'!U11="","",'Engine'!U11) | D27: =IF('Engine'!T11="","",'Engine'!T11) | E27: =IF('Engine'!S11="","",'Engine'!S11) | F27: =IF(C27="","",IF(C27<AsOf,(AsOf-C27)&IF(AsOf-C27=1," day"," days")&" overdue",IF(C27=AsOf,"today","in "&(C27-AsOf)&IF(C27-AsOf=1," day"," days")))) | I27: ='Engine'!V11
B28: =IF(WeekAlertCount=0,"🟢 Nothing due this week.",IF(WeekAlertCount>10,"+ "&(WeekAlertCount-10)&" more due this week","All "&WeekAlertCount&" shown."))
B30: 📝 FRIDAY REVIEW — the numbers (automatic)
B31: ="Paid this week ("&CurSym&")" | C31: =SUMIFS('Payments'!$N$6:$N$1005,'Payments'!$M$6:$M$1005,">="&WeekStartDate,'Payments'!$M$6:$M$1005,"<="&WeekEndDate)
B32: Change orders approved this week | C32: =COUNTIFS('Change Orders'!$L$7:$L$1006,"Approved",'Change Orders'!$M$7:$M$1006,">="&WeekStartDate,'Change Orders'!$M$7:$M$1006,"<="&WeekEndDate)
B33: ="…their extra cost ("&CurSym&")" | C33: =SUMIFS('Change Orders'!$J$7:$J$1006,'Change Orders'!$L$7:$L$1006,"Approved",'Change Orders'!$M$7:$M$1006,">="&WeekStartDate,'Change Orders'!$M$7:$M$1006,"<="&WeekEndDate)
B34: Tasks completed this week | C34: =COUNTIFS('Timeline'!$M$7:$M$1006,"Done",'Timeline'!$N$7:$N$1006,">="&WeekStartDate,'Timeline'!$N$7:$N$1006,"<="&WeekEndDate)
B35: Issues opened this week | C35: =COUNTIFS('Issues & Punch List'!$D$8:$D$1007,">="&WeekStartDate,'Issues & Punch List'!$D$8:$D$1007,"<="&WeekEndDate)
B36: Issues closed this week | C36: =COUNTIFS('Issues & Punch List'!$M$8:$M$1007,">="&WeekStartDate,'Issues & Punch List'!$M$8:$M$1007,"<="&WeekEndDate)
B38: 📝 FRIDAY REVIEW — your notes (type in the yellow boxes)
B39: What was completed?
B40: Electrical first fix 90% done; shower enclosure delivered.
B44: What was delayed?
B45: Plumbing rough-in (pipe re-route) — now 10 days late.
B49: What changed?
B50: EV charger change order requested by electrician (pending).
...

Sheet Budget
B1: 💶 Budget
B2: What this tab does: compares your budget per category with what you have committed, invoiced and paid, and forecasts the final cost.
B3: © 2026 Hang Nguyen — Renovation OS. Licensed to the original purchaser for personal use only. Do not share, copy, resell or redistribute.
B4: ="Working budget ("&CurSym&")" | C4: =WorkBudget | E4: Sum of category budgets | G4: =BudgetSum | H4: =IF(WorkBudget=0,"",IF(ABS(BudgetSum-WorkBudget)<1,"✓ matches",IF(BudgetSum>WorkBudget,"▲ "&FIXED(BudgetSum-WorkBudget,0)&" more than working budget","▼ "&FIXED(WorkBudget-BudgetSum,0)&" not yet allocated")))
B7: Category | C7: ="Budget ("&CurSym&")" | D7: Stage | E7: ="Best quote ("&CurSym&")" | F7: ="Contracted ("&CurSym&")" | G7: ="Materials ("&CurSym&")" | H7: ="Approved changes ("&CurSym&")" | I7: ="Committed ("&CurSym&")" | J7: ="Invoiced ("&CurSym&")" | K7: ="Paid ("&CurSym&")" | L7: ="Forecast ("&CurSym&")" | M7: ="Variance ("&CurSym&")" | N7: Status | O7: lvl | P7: chart key
B8: Demolition | C8: 4000 | D8: Complete | E8: =IF(B8="","",IFERROR(1/SUMPRODUCT(MAX((QBlockCat=B8)*QBlockInv)),"")) | F8: =IF(B8="","",SUMIFS('Contractors'!$I$6:$I$1005,'Contractors'!$D$6:$D$1005,B8,'Contractors'!$L$6:$L$1005,"Yes")) | G8: =IF(B8="","",SUMIFS('Selections & Orders'!$L$8:$L$1007,'Selections & Orders'!$D$8:$D$1007,B8)) | H8: =IF(B8="","",SUMIFS('Change Orders'!$J$7:$J$1006,'Change Orders'!$F$7:$F$1006,B8,'Change Orders'!$L$7:$L$1006,"Approved")) | I8: =IF(B8="","",F8+G8+H8) | J8: =IF(B8="","",SUMIFS('Payments'!$L$6:$L$1005,'Payments'!$P$6:$P$1005,B8)) | K8: =IF(B8="","",SUMIFS('Payments'!$N$6:$N$1005,'Payments'!$P$6:$P$1005,B8)) | L8: =IF(B8="","",IF(OR(D8="Estimating",D8=""),MAX(C8,E8,I8,J8),MAX(I8,J8))) | M8: =IF(B8="","",C8-L8) | N8: =IF(O8="","",IF(O8=0,"🟢 On track",IF(O8=1,"🟡 Watch","🔴 Over"))) | O8: =IF(B8="","",IF(L8<=C8,0,IF(L8<=C8*(1+BudgetWarnPct),1,2))) | P8: =IF(B8="","",IF(MAX(C8,L8)>0,MAX(C8,L8)+ROW()/100000,""))
B9: Structural | C9: 9000 | D9: Complete | E9: =IF(B9="","",IFERROR(1/SUMPRODUCT(MAX((QBlockCat=B9)*QBlockInv)),"")) | F9: =IF(B9="","",SUMIFS('Contractors'!$I$6:$I$1005,'Contractors'!$D$6:$D$1005,B9,'Contractors'!$L$6:$L$1005,"Yes")) | G9: =IF(B9="","",SUMIFS('Selections & Orders'!$L$8:$L$1007,'Selections & Orders'!$D$8:$D$1007,B9)) | H9: =IF(B9="","",SUMIFS('Change Orders'!$J$7:$J$1006,'Change Orders'!$F$7:$F$1006,B9,'Change Orders'!$L$7:$L$1006,"Approved")) | I9: =IF(B9="","",F9+G9+H9) | J9: =IF(B9="","",SUMIFS('Payments'!$L$6:$L$1005,'Payments'!$P$6:$P$1005,B9)) | K9: =IF(B9="","",SUMIFS('Payments'!$N$6:$N$1005,'Payments'!$P$6:$P$1005,B9)) | L9: =IF(B9="","",IF(OR(D9="Estimating",D9=""),MAX(C9,E9,I9,J9),MAX(I9,J9))) | M9: =IF(B9="","",C9-L9) | N9: =IF(O9="","",IF(O9=0,"🟢 On track",IF(O9=1,"🟡 Watch","🔴 Over"))) | O9: =IF(B9="","",IF(L9<=C9,0,IF(L9<=C9*(1+BudgetWarnPct),1,2))) | P9: =IF(B9="","",IF(MAX(C9,L9)>0,MAX(C9,L9)+ROW()/100000,""))
B10: Plumbing | C10: 9500 | D10: Contracted | E10: =IF(B10="","",IFERROR(1/SUMPRODUCT(MAX((QBlockCat=B10)*QBlockInv)),"")) | F10: =IF(B10="","",SUMIFS('Contractors'!$I$6:$I$1005,'Contractors'!$D$6:$D$1005,B10,'Contractors'!$L$6:$L$1005,"Yes")) | G10: =IF(B10="","",SUMIFS('Selections & Orders'!$L$8:$L$1007,'Selections & Orders'!$D$8:$D$1007,B10)) | H10: =IF(B10="","",SUMIFS('Change Orders'!$J$7:$J$1006,'Change Orders'!$F$7:$F$1006,B10,'Change Orders'!$L$7:$L$1006,"Approved")) | I10: =IF(B10="","",F10+G10+H10) | J10: =IF(B10="","",SUMIFS('Payments'!$L$6:$L$1005,'Payments'!$P$6:$P$1005,B10)) | K10: =IF(B10="","",SUMIFS('Payments'!$N$6:$N$1005,'Payments'!$P$6:$P$1005,B10)) | L10: =IF(B10="","",IF(OR(D10="Estimating",D10=""),MAX(C10,E10,I10,J10),MAX(I10,J10))) | M10: =IF(B10="","",C10-L10) | N10: =IF(O10="","",IF(O10=0,"🟢 On track",IF(O10=1,"🟡 Watch","🔴 Over"))) | O10: =IF(B10="","",IF(L10<=C10,0,IF(L10<=C10*(1+BudgetWarnPct),1,2))) | P10: =IF(B10="","",IF(MAX(C10,L10)>0,MAX(C10,L10)+ROW()/100000,""))
B11: Electrical | C11: 10000 | D11: Contracted | E11: =IF(B11="","",IFERROR(1/SUMPRODUCT(MAX((QBlockCat=B11)*QBlockInv)),"")) | F11: =IF(B11="","",SUMIFS('Contractors'!$I$6:$I$1005,'Contractors'!$D$6:$D$1005,B11,'Contractors'!$L$6:$L$1005,"Yes")) | G11: =IF(B11="","",SUMIFS('Selections & Orders'!$L$8:$L$1007,'Selections & Orders'!$D$8:$D$1007,B11)) | H11: =IF(B11="","",SUMIFS('Change Orders'!$J$7:$J$1006,'Change Orders'!$F$7:$F$1006,B11,'Change Orders'!$L$7:$L$1006,"Approved")) | I11: =IF(B11="","",F11+G11+H11) | J11: =IF(B11="","",SUMIFS('Payments'!$L$6:$L$1005,'Payments'!$P$6:$P$1005,B11)) | K11: =IF(B11="","",SUMIFS('Payments'!$N$6:$N$1005,'Payments'!$P$6:$P$1005,B11)) | L11: =IF(B11="","",IF(OR(D11="Estimating",D11=""),MAX(C11,E11,I11,J11),MAX(I11,J11))) | M11: =IF(B11="","",C11-L11) | N11: =IF(O11="","",IF(O11=0,"🟢 On track",IF(O11=1,"🟡 Watch","🔴 Over"))) | O11: =IF(B11="","",IF(L11<=C11,0,IF(L11<=C11*(1+BudgetWarnPct),1,2))) | P11: =IF(B11="","",IF(MAX(C11,L11)>0,MAX(C11,L11)+ROW()/100000,""))
B12: HVAC | C12: 9000 | D12: Contracted | E12: =IF(B12="","",IFERROR(1/SUMPRODUCT(MAX((QBlockCat=B12)*QBlockInv)),"")) | F12: =IF(B12="","",SUMIFS('Contractors'!$I$6:$I$1005,'Contractors'!$D$6:$D$1005,B12,'Contractors'!$L$6:$L$1005,"Yes")) | G12: =IF(B12="","",SUMIFS('Selections & Orders'!$L$8:$L$1007,'Selections & Orders'!$D$8:$D$1007,B12)) | H12: =IF(B12="","",SUMIFS('Change Orders'!$J$7:$J$1006,'Change Orders'!$F$7:$F$1006,B12,'Change Orders'!$L$7:$L$1006,"Approved")) | I12: =IF(B12="","",F12+G12+H12) | J12: =IF(B12="","",SUMIFS('Payments'!$L$6:$L$1005,'Payments'!$P$6:$P$1005,B12)) | K12: =IF(B12="","",SUMIFS('Payments'!$N$6:$N$1005,'Payments'!$P$6:$P$1005,B12)) | L12: =IF(B12="","",IF(OR(D12="Estimating",D12=""),MAX(C12,E12,I12,J12),MAX(I12,J12))) | M12: =IF(B12="","",C12-L12) | N12: =IF(O12="","",IF(O12=0,"🟢 On track",IF(O12=1,"🟡 Watch","🔴 Over"))) | O12: =IF(B12="","",IF(L12<=C12,0,IF(L12<=C12*(1+BudgetWarnPct),1,2))) | P12: =IF(B12="","",IF(MAX(C12,L12)>0,MAX(C12,L12)+ROW()/100000,""))
B13: Windows & doors | C13: 12000 | D13: Contracted | E13: =IF(B13="","",IFERROR(1/SUMPRODUCT(MAX((QBlockCat=B13)*QBlockInv)),"")) | F13: =IF(B13="","",SUMIFS('Contractors'!$I$6:$I$1005,'Contractors'!$D$6:$D$1005,B13,'Contractors'!$L$6:$L$1005,"Yes")) | G13: =IF(B13="","",SUMIFS('Selections & Orders'!$L$8:$L$1007,'Selections & Orders'!$D$8:$D$1007,B13)) | H13: =IF(B13="","",SUMIFS('Change Orders'!$J$7:$J$1006,'Change Orders'!$F$7:$F$1006,B13,'Change Orders'!$L$7:$L$1006,"Approved")) | I13: =IF(B13="","",F13+G13+H13) | J13: =IF(B13="","",SUMIFS('Payments'!$L$6:$L$1005,'Payments'!$P$6:$P$1005,B13)) | K13: =IF(B13="","",SUMIFS('Payments'!$N$6:$N$1005,'Payments'!$P$6:$P$1005,B13)) | L13: =IF(B13="","",IF(OR(D13="Estimating",D13=""),MAX(C13,E13,I13,J13),MAX(I13,J13))) | M13: =IF(B13="","",C13-L13) | N13: =IF(O13="","",IF(O13=0,"🟢 On track",IF(O13=1,"🟡 Watch","🔴 Over"))) | O13: =IF(B13="","",IF(L13<=C13,0,IF(L13<=C13*(1+BudgetWarnPct),1,2))) | P13: =IF(B13="","",IF(MAX(C13,L13)>0,MAX(C13,L13)+ROW()/100000,""))
B14: Roofing | C14: 3000 | D14: Estimating | E14: =IF(B14="","",IFERROR(1/SUMPRODUCT(MAX((QBlockCat=B14)*QBlockInv)),"")) | F14: =IF(B14="","",SUMIFS('Contractors'!$I$6:$I$1005,'Contractors'!$D$6:$D$1005,B14,'Contractors'!$L$6:$L$1005,"Yes")) | G14: =IF(B14="","",SUMIFS('Selections & Orders'!$L$8:$L$1007,'Selections & Orders'!$D$8:$D$1007,B14)) | H14: =IF(B14="","",SUMIFS('Change Orders'!$J$7:$J$1006,'Change Orders'!$F$7:$F$1006,B14,'Change Orders'!$L$7:$L$1006,"Approved")) | I14: =IF(B14="","",F14+G14+H14) | J14: =IF(B14="","",SUMIFS('Payments'!$L$6:$L$1005,'Payments'!$P$6:$P$1005,B14)) | K14: =IF(B14="","",SUMIFS('Payments'!$N$6:$N$1005,'Payments'!$P$6:$P$1005,B14)) | L14: =IF(B14="","",IF(OR(D14="Estimating",D14=""),MAX(C14,E14,I14,J14),MAX(I14,J14))) | M14: =IF(B14="","",C14-L14) | N14: =IF(O14="","",IF(O14=0,"🟢 On track",IF(O14=1,"🟡 Watch","🔴 Over"))) | O14: =IF(B14="","",IF(L14<=C14,0,IF(L14<=C14*(1+BudgetWarnPct),1,2))) | P14: =IF(B14="","",IF(MAX(C14,L14)>0,MAX(C14,L14)+ROW()/100000,""))
B15: Kitchen | C15: 20000 | D15: Contracted | E15: =IF(B15="","",IFERROR(1/SUMPRODUCT(MAX((QBlockCat=B15)*QBlockInv)),"")) | F15: =IF(B15="","",SUMIFS('Contractors'!$I$6:$I$1005,'Contractors'!$D$6:$D$1005,B15,'Contractors'!$L$6:$L$1005,"Yes")) | G15: =IF(B15="","",SUMIFS('Selections & Orders'!$L$8:$L$1007,'Selections & Orders'!$D$8:$D$1007,B15)) | H15: =IF(B15="","",SUMIFS('Change Orders'!$J$7:$J$1006,'Change Orders'!$F$7:$F$1006,B15,'Change Orders'!$L$7:$L$1006,"Approved")) | I15: =IF(B15="","",F15+G15+H15) | J15: =IF(B15="","",SUMIFS('Payments'!$L$6:$L$1005,'Payments'!$P$6:$P$1005,B15)) | K15: =IF(B15="","",SUMIFS('Payments'!$N$6:$N$1005,'Payments'!$P$6:$P$1005,B15)) | L15: =IF(B15="","",IF(OR(D15="Estimating",D15=""),MAX(C15,E15,I15,J15),MAX(I15,J15))) | M15: =IF(B15="","",C15-L15) | N15: =IF(O15="","",IF(O15=0,"🟢 On track",IF(O15=1,"🟡 Watch","🔴 Over"))) | O15: =IF(B15="","",IF(L15<=C15,0,IF(L15<=C15*(1+BudgetWarnPct),1,2))) | P15: =IF(B15="","",IF(MAX(C15,L15)>0,MAX(C15,L15)+ROW()/100000,""))
B16: Bathrooms | C16: 15000 | D16: Contracted | E16: =IF(B16="","",IFERROR(1/SUMPRODUCT(MAX((QBlockCat=B16)*QBlockInv)),"")) | F16: =IF(B16="","",SUMIFS('Contractors'!$I$6:$I$1005,'Contractors'!$D$6:$D$1005,B16,'Contractors'!$L$6:$L$1005,"Yes")) | G16: =IF(B16="","",SUMIFS('Selections & Orders'!$L$8:$L$1007,'Selections & Orders'!$D$8:$D$1007,B16)) | H16: =IF(B16="","",SUMIFS('Change Orders'!$J$7:$J$1006,'Change Orders'!$F$7:$F$1006,B16,'Change Orders'!$L$7:$L$1006,"Approved")) | I16: =IF(B16="","",F16+G16+H16) | J16: =IF(B16="","",SUMIFS('Payments'!$L$6:$L$1005,'Payments'!$P$6:$P$1005,B16)) | K16: =IF(B16="","",SUMIFS('Payments'!$N$6:$N$1005,'Payments'!$P$6:$P$1005,B16)) | L16: =IF(B16="","",IF(OR(D16="Estimating",D16=""),MAX(C16,E16,I16,J16),MAX(I16,J16))) | M16: =IF(B16="","",C16-L16) | N16: =IF(O16="","",IF(O16=0,"🟢 On track",IF(O16=1,"🟡 Watch","🔴 Over"))) | O16: =IF(B16="","",IF(L16<=C16,0,IF(L16<=C16*(1+BudgetWarnPct),1,2))) | P16: =IF(B16="","",IF(MAX(C16,L16)>0,MAX(C16,L16)+ROW()/100000,""))
B17: Flooring | C17: 8500 | D17: Estimating | E17: =IF(B17="","",IFERROR(1/SUMPRODUCT(MAX((QBlockCat=B17)*QBlockInv)),"")) | F17: =IF(B17="","",SUMIFS('Contractors'!$I$6:$I$1005,'Contractors'!$D$6:$D$1005,B17,'Contractors'!$L$6:$L$1005,"Yes")) | G17: =IF(B17="","",SUMIFS('Selections & Orders'!$L$8:$L$1007,'Selections & Orders'!$D$8:$D$1007,B17)) | H17: =IF(B17="","",SUMIFS('Change Orders'!$J$7:$J$1006,'Change Orders'!$F$7:$F$1006,B17,'Change Orders'!$L$7:$L$1006,"Approved")) | I17: =IF(B17="","",F17+G17+H17) | J17: =IF(B17="","",SUMIFS('Payments'!$L$6:$L$1005,'Payments'!$P$6:$P$1005,B17)) | K17: =IF(B17="","",SUMIFS('Payments'!$N$6:$N$1005,'Payments'!$P$6:$P$1005,B17)) | L17: =IF(B17="","",IF(OR(D17="Estimating",D17=""),MAX(C17,E17,I17,J17),MAX(I17,J17))) | M17: =IF(B17="","",C17-L17) | N17: =IF(O17="","",IF(O17=0,"🟢 On track",IF(O17=1,"🟡 Watch","🔴 Over"))) | O17: =IF(B17="","",IF(L17<=C17,0,IF(L17<=C17*(1+BudgetWarnPct),1,2))) | P17: =IF(B17="","",IF(MAX(C17,L17)>0,MAX(C17,L17)+ROW()/100000,""))
B18: Painting | C18: 4500 | D18: Estimating | E18: =IF(B18="","",IFERROR(1/SUMPRODUCT(MAX((QBlockCat=B18)*QBlockInv)),"")) | F18: =IF(B18="","",SUMIFS('Contractors'!$I$6:$I$1005,'Contractors'!$D$6:$D$1005,B18,'Contractors'!$L$6:$L$1005,"Yes")) | G18: =IF(B18="","",SUMIFS('Selections & Orders'!$L$8:$L$1007,'Selections & Orders'!$D$8:$D$1007,B18)) | H18: =IF(B18="","",SUMIFS('Change Orders'!$J$7:$J$1006,'Change Orders'!$F$7:$F$1006,B18,'Change Orders'!$L$7:$L$1006,"Approved")) | I18: =IF(B18="","",F18+G18+H18) | J18: =IF(B18="","",SUMIFS('Payments'!$L$6:$L$1005,'Payments'!$P$6:$P$1005,B18)) | K18: =IF(B18="","",SUMIFS('Payments'!$N$6:$N$1005,'Payments'!$P$6:$P$1005,B18)) | L18: =IF(B18="","",IF(OR(D18="Estimating",D18=""),MAX(C18,E18,I18,J18),MAX(I18,J18))) | M18: =IF(B18="","",C18-L18) | N18: =IF(O18="","",IF(O18=0,"🟢 On track",IF(O18=1,"🟡 Watch","🔴 Over"))) | O18: =IF(B18="","",IF(L18<=C18,0,IF(L18<=C18*(1+BudgetWarnPct),1,2))) | P18: =IF(B18="","",IF(MAX(C18,L18)>0,MAX(C18,L18)+ROW()/100000,""))
B19: Landscaping | C19: 2000 | D19: Estimating | E19: =IF(B19="","",IFERROR(1/SUMPRODUCT(MAX((QBlockCat=B19)*QBlockInv)),"")) | F19: =IF(B19="","",SUMIFS('Contractors'!$I$6:$I$1005,'Contractors'!$D$6:$D$1005,B19,'Contractors'!$L$6:$L$1005,"Yes")) | G19: =IF(B19="","",SUMIFS('Selections & Orders'!$L$8:$L$1007,'Selections & Orders'!$D$8:$D$1007,B19)) | H19: =IF(B19="","",SUMIFS('Change Orders'!$J$7:$J$1006,'Change Orders'!$F$7:$F$1006,B19,'Change Orders'!$L$7:$L$1006,"Approved")) | I19: =IF(B19="","",F19+G19+H19) | J19: =IF(B19="","",SUMIFS('Payments'!$L$6:$L$1005,'Payments'!$P$6:$P$1005,B19)) | K19: =IF(B19="","",SUMIFS('Payments'!$N$6:$N$1005,'Payments'!$P$6:$P$1005,B19)) | L19: =IF(B19="","",IF(OR(D19="Estimating",D19=""),MAX(C19,E19,I19,J19),MAX(I19,J19))) | M19: =IF(B19="","",C19-L19) | N19: =IF(O19="","",IF(O19=0,"🟢 On track",IF(O19=1,"🟡 Watch","🔴 Over"))) | O19: =IF(B19="","",IF(L19<=C19,0,IF(L19<=C19*(1+BudgetWarnPct),1,2))) | P19: =IF(B19="","",IF(MAX(C19,L19)>0,MAX(C19,L19)+ROW()/100000,""))
... B25: Other | C25: 500 | D25: Estimating | E25: =IF(B25="","",IFERROR(1/SUMPRODUCT(MAX((QBlockCat=B25)*QBlockInv)),"")) | F25: =IF(B25="","",SUMIFS('Contractors'!$I$6:$I$1005,'Contractors'!$D$6:$D$1005,B25,'Contractors'!$L$6:$L$1005,"Yes")) | G25: =IF(B25="","",SUMIFS('Selections & Orders'!$L$8:$L$1007,'Selections & Orders'!$D$8:$D$1007,B25)) | H25: =IF(B25="","",SUMIFS('Change Orders'!$J$7:$J$1006,'Change Orders'!$F$7:$F$1006,B25,'Change Orders'!$L$7:$L$1006,"Approved")) | I25: =IF(B25="","",F25+G25+H25) | J25: =IF(B25="","",SUMIFS('Payments'!$L$6:$L$1005,'Payments'!$P$6:$P$1005,B25)) | K25: =IF(B25="","",SUMIFS('Payments'!$N$6:$N$1005,'Payments'!$P$6:$P$1005,B25)) | L25: =IF(B25="","",IF(OR(D25="Estimating",D25=""),MAX(C25,E25,I25,J25),MAX(I25,J25))) | M25: =IF(B25="","",C25-L25) | N25: =IF(O25="","",IF(O25=0,"🟢 On track",IF(O25=1,"🟡 Watch","🔴 Over"))) | O25: =IF(B25="","",IF(L25<=C25,0,IF(L25<=C25*(1+BudgetWarnPct),1,2))) | P25: =IF(B25="","",IF(MAX(C25,L25)>0,MAX(C25,L25)+ROW()/100000,""))
E26: =IF(B26="","",IFERROR(1/SUMPRODUCT(MAX((QBlockCat=B26)*QBlockInv)),"")) | F26: =IF(B26="","",SUMIFS('Contractors'!$I$6:$I$1005,'Contractors'!$D$6:$D$1005,B26,'Contractors'!$L$6:$L$1005,"Yes")) | G26: =IF(B26="","",SUMIFS('Selections & Orders'!$L$8:$L$1007,'Selections & Orders'!$D$8:$D$1007,B26)) | H26: =IF(B26="","",SUMIFS('Change Orders'!$J$7:$J$1006,'Change Orders'!$F$7:$F$1006,B26,'Change Orders'!$L$7:$L$1006,"Approved")) | I26: =IF(B26="","",F26+G26+H26) | J26: =IF(B26="","",SUMIFS('Payments'!$L$6:$L$1005,'Payments'!$P$6:$P$1005,B26)) | K26: =IF(B26="","",SUMIFS('Payments'!$N$6:$N$1005,'Payments'!$P$6:$P$1005,B26)) | L26: =IF(B26="","",IF(OR(D26="Estimating",D26=""),MAX(C26,E26,I26,J26),MAX(I26,J26))) | M26: =IF(B26="","",C26-L26) | N26: =IF(O26="","",IF(O26=0,"🟢 On track",IF(O26=1,"🟡 Watch","🔴 Over"))) | O26: =IF(B26="","",IF(L26<=C26,0,IF(L26<=C26*(1+BudgetWarnPct),1,2))) | P26: =IF(B26="","",IF(MAX(C26,L26)>0,MAX(C26,L26)+ROW()/100000,""))
E27: =IF(B27="","",IFERROR(1/SUMPRODUCT(MAX((QBlockCat=B27)*QBlockInv)),"")) | F27: =IF(B27="","",SUMIFS('Contractors'!$I$6:$I$1005,'Contractors'!$D$6:$D$1005,B27,'Contractors'!$L$6:$L$1005,"Yes")) | G27: =IF(B27="","",SUMIFS('Selections & Orders'!$L$8:$L$1007,'Selections & Orders'!$D$8:$D$1007,B27)) | H27: =IF(B27="","",SUMIFS('Change Orders'!$J$7:$J$1006,'Change Orders'!$F$7:$F$1006,B27,'Change Orders'!$L$7:$L$1006,"Approved")) | I27: =IF(B27="","",F27+G27+H27) | J27: =IF(B27="","",SUMIFS('Payments'!$L$6:$L$1005,'Payments'!$P$6:$P$1005,B27)) | K27: =IF(B27="","",SUMIFS('Payments'!$N$6:$N$1005,'Payments'!$P$6:$P$1005,B27)) | L27: =IF(B27="","",IF(OR(D27="Estimating",D27=""),MAX(C27,E27,I27,J27),MAX(I27,J27))) | M27: =IF(B27="","",C27-L27) | N27: =IF(O27="","",IF(O27=0,"🟢 On track",IF(O27=1,"🟡 Watch","🔴 Over"))) | O27: =IF(B27="","",IF(L27<=C27,0,IF(L27<=C27*(1+BudgetWarnPct),1,2))) | P27: =IF(B27="","",IF(MAX(C27,L27)>0,MAX(C27,L27)+ROW()/100000,""))
E28: =IF(B28="","",IFERROR(1/SUMPRODUCT(MAX((QBlockCat=B28)*QBlockInv)),"")) | F28: =IF(B28="","",SUMIFS('Contractors'!$I$6:$I$1005,'Contractors'!$D$6:$D$1005,B28,'Contractors'!$L$6:$L$1005,"Yes")) | G28: =IF(B28="","",SUMIFS('Selections & Orders'!$L$8:$L$1007,'Selections & Orders'!$D$8:$D$1007,B28)) | H28: =IF(B28="","",SUMIFS('Change Orders'!$J$7:$J$1006,'Change Orders'!$F$7:$F$1006,B28,'Change Orders'!$L$7:$L$1006,"Approved")) | I28: =IF(B28="","",F28+G28+H28) | J28: =IF(B28="","",SUMIFS('Payments'!$L$6:$L$1005,'Payments'!$P$6:$P$1005,B28)) | K28: =IF(B28="","",SUMIFS('Payments'!$N$6:$N$1005,'Payments'!$P$6:$P$1005,B28)) | L28: =IF(B28="","",IF(OR(D28="Estimating",D28=""),MAX(C28,E28,I28,J28),MAX(I28,J28))) | M28: =IF(B28="","",C28-L28) | N28: =IF(O28="","",IF(O28=0,"🟢 On track",IF(O28=1,"🟡 Watch","🔴 Over"))) | O28: =IF(B28="","",IF(L28<=C28,0,IF(L28<=C28*(1+BudgetWarnPct),1,2))) | P28: =IF(B28="","",IF(MAX(C28,L28)>0,MAX(C28,L28)+ROW()/100000,""))
E29: =IF(B29="","",IFERROR(1/SUMPRODUCT(MAX((QBlockCat=B29)*QBlockInv)),"")) | F29: =IF(B29="","",SUMIFS('Contractors'!$I$6:$I$1005,'Contractors'!$D$6:$D$1005,B29,'Contractors'!$L$6:$L$1005,"Yes")) | G29: =IF(B29="","",SUMIFS('Selections & Orders'!$L$8:$L$1007,'Selections & Orders'!$D$8:$D$1007,B29)) | H29: =IF(B29="","",SUMIFS('Change Orders'!$J$7:$J$1006,'Change Orders'!$F$7:$F$1006,B29,'Change Orders'!$L$7:$L$1006,"Approved")) | I29: =IF(B29="","",F29+G29+H29) | J29: =IF(B29="","",SUMIFS('Payments'!$L$6:$L$1005,'Payments'!$P$6:$P$1005,B29)) | K29: =IF(B29="","",SUMIFS('Payments'!$N$6:$N$1005,'Payments'!$P$6:$P$1005,B29)) | L29: =IF(B29="","",IF(OR(D29="Estimating",D29=""),MAX(C29,E29,I29,J29),MAX(I29,J29))) | M29: =IF(B29="","",C29-L29) | N29: =IF(O29="","",IF(O29=0,"🟢 On track",IF(O29=1,"🟡 Watch","🔴 Over"))) | O29: =IF(B29="","",IF(L29<=C29,0,IF(L29<=C29*(1+BudgetWarnPct),1,2))) | P29: =IF(B29="","",IF(MAX(C29,L29)>0,MAX(C29,L29)+ROW()/100000,""))
E30: =IF(B30="","",IFERROR(1/SUMPRODUCT(MAX((QBlockCat=B30)*QBlockInv)),"")) | F30: =IF(B30="","",SUMIFS('Contractors'!$I$6:$I$1005,'Contractors'!$D$6:$D$1005,B30,'Contractors'!$L$6:$L$1005,"Yes")) | G30: =IF(B30="","",SUMIFS('Selections & Orders'!$L$8:$L$1007,'Selections & Orders'!$D$8:$D$1007,B30)) | H30: =IF(B30="","",SUMIFS('Change Orders'!$J$7:$J$1006,'Change Orders'!$F$7:$F$1006,B30,'Change Orders'!$L$7:$L$1006,"Approved")) | I30: =IF(B30="","",F30+G30+H30) | J30: =IF(B30="","",SUMIFS('Payments'!$L$6:$L$1005,'Payments'!$P$6:$P$1005,B30)) | K30: =IF(B30="","",SUMIFS('Payments'!$N$6:$N$1005,'Payments'!$P$6:$P$1005,B30)) | L30: =IF(B30="","",IF(OR(D30="Estimating",D30=""),MAX(C30,E30,I30,J30),MAX(I30,J30))) | M30: =IF(B30="","",C30-L30) | N30: =IF(O30="","",IF(O30=0,"🟢 On track",IF(O30=1,"🟡 Watch","🔴 Over"))) | O30: =IF(B30="","",IF(L30<=C30,0,IF(L30<=C30*(1+BudgetWarnPct),1,2))) | P30: =IF(B30="","",IF(MAX(C30,L30)>0,MAX(C30,L30)+ROW()/100000,""))
E31: =IF(B31="","",IFERROR(1/SUMPRODUCT(MAX((QBlockCat=B31)*QBlockInv)),"")) | F31: =IF(B31="","",SUMIFS('Contractors'!$I$6:$I$1005,'Contractors'!$D$6:$D$1005,B31,'Contractors'!$L$6:$L$1005,"Yes")) | G31: =IF(B31="","",SUMIFS('Selections & Orders'!$L$8:$L$1007,'Selections & Orders'!$D$8:$D$1007,B31)) | H31: =IF(B31="","",SUMIFS('Change Orders'!$J$7:$J$1006,'Change Orders'!$F$7:$F$1006,B31,'Change Orders'!$L$7:$L$1006,"Approved")) | I31: =IF(B31="","",F31+G31+H31) | J31: =IF(B31="","",SUMIFS('Payments'!$L$6:$L$1005,'Payments'!$P$6:$P$1005,B31)) | K31: =IF(B31="","",SUMIFS('Payments'!$N$6:$N$1005,'Payments'!$P$6:$P$1005,B31)) | L31: =IF(B31="","",IF(OR(D31="Estimating",D31=""),MAX(C31,E31,I31,J31),MAX(I31,J31))) | M31: =IF(B31="","",C31-L31) | N31: =IF(O31="","",IF(O31=0,"🟢 On track",IF(O31=1,"🟡 Watch","🔴 Over"))) | O31: =IF(B31="","",IF(L31<=C31,0,IF(L31<=C31*(1+BudgetWarnPct),1,2))) | P31: =IF(B31="","",IF(MAX(C31,L31)>0,MAX(C31,L31)+ROW()/100000,""))
E32: =IF(B32="","",IFERROR(1/SUMPRODUCT(MAX((QBlockCat=B32)*QBlockInv)),"")) | F32: =IF(B32="","",SUMIFS('Contractors'!$I$6:$I$1005,'Contractors'!$D$6:$D$1005,B32,'Contractors'!$L$6:$L$1005,"Yes")) | G32: =IF(B32="","",SUMIFS('Selections & Orders'!$L$8:$L$1007,'Selections & Orders'!$D$8:$D$1007,B32)) | H32: =IF(B32="","",SUMIFS('Change Orders'!$J$7:$J$1006,'Change Orders'!$F$7:$F$1006,B32,'Change Orders'!$L$7:$L$1006,"Approved")) | I32: =IF(B32="","",F32+G32+H32) | J32: =IF(B32="","",SUMIFS('Payments'!$L$6:$L$1005,'Payments'!$P$6:$P$1005,B32)) | K32: =IF(B32="","",SUMIFS('Payments'!$N$6:$N$1005,'Payments'!$P$6:$P$1005,B32)) | L32: =IF(B32="","",IF(OR(D32="Estimating",D32=""),MAX(C32,E32,I32,J32),MAX(I32,J32))) | M32: =IF(B32="","",C32-L32) | N32: =IF(O32="","",IF(O32=0,"🟢 On track",IF(O32=1,"🟡 Watch","🔴 Over"))) | O32: =IF(B32="","",IF(L32<=C32,0,IF(L32<=C32*(1+BudgetWarnPct),1,2))) | P32: =IF(B32="","",IF(MAX(C32,L32)>0,MAX(C32,L32)+ROW()/100000,""))
E33: =IF(B33="","",IFERROR(1/SUMPRODUCT(MAX((QBlockCat=B33)*QBlockInv)),"")) | F33: =IF(B33="","",SUMIFS('Contractors'!$I$6:$I$1005,'Contractors'!$D$6:$D$1005,B33,'Contractors'!$L$6:$L$1005,"Yes")) | G33: =IF(B33="","",SUMIFS('Selections & Orders'!$L$8:$L$1007,'Selections & Orders'!$D$8:$D$1007,B33)) | H33: =IF(B33="","",SUMIFS('Change Orders'!$J$7:$J$1006,'Change Orders'!$F$7:$F$1006,B33,'Change Orders'!$L$7:$L$1006,"Approved")) | I33: =IF(B33="","",F33+G33+H33) | J33: =IF(B33="","",SUMIFS('Payments'!$L$6:$L$1005,'Payments'!$P$6:$P$1005,B33)) | K33: =IF(B33="","",SUMIFS('Payments'!$N$6:$N$1005,'Payments'!$P$6:$P$1005,B33)) | L33: =IF(B33="","",IF(OR(D33="Estimating",D33=""),MAX(C33,E33,I33,J33),MAX(I33,J33))) | M33: =IF(B33="","",C33-L33) | N33: =IF(O33="","",IF(O33=0,"🟢 On track",IF(O33=1,"🟡 Watch","🔴 Over"))) | O33: =IF(B33="","",IF(L33<=C33,0,IF(L33<=C33*(1+BudgetWarnPct),1,2))) | P33: =IF(B33="","",IF(MAX(C33,L33)>0,MAX(C33,L33)+ROW()/100000,""))
E34: =IF(B34="","",IFERROR(1/SUMPRODUCT(MAX((QBlockCat=B34)*QBlockInv)),"")) | F34: =IF(B34="","",SUMIFS('Contractors'!$I$6:$I$1005,'Contractors'!$D$6:$D$1005,B34,'Contractors'!$L$6:$L$1005,"Yes")) | G34: =IF(B34="","",SUMIFS('Selections & Orders'!$L$8:$L$1007,'Selections & Orders'!$D$8:$D$1007,B34)) | H34: =IF(B34="","",SUMIFS('Change Orders'!$J$7:$J$1006,'Change Orders'!$F$7:$F$1006,B34,'Change Orders'!$L$7:$L$1006,"Approved")) | I34: =IF(B34="","",F34+G34+H34) | J34: =IF(B34="","",SUMIFS('Payments'!$L$6:$L$1005,'Payments'!$P$6:$P$1005,B34)) | K34: =IF(B34="","",SUMIFS('Payments'!$N$6:$N$1005,'Payments'!$P$6:$P$1005,B34)) | L34: =IF(B34="","",IF(OR(D34="Estimating",D34=""),MAX(C34,E34,I34,J34),MAX(I34,J34))) | M34: =IF(B34="","",C34-L34) | N34: =IF(O34="","",IF(O34=0,"🟢 On track",IF(O34=1,"🟡 Watch","🔴 Over"))) | O34: =IF(B34="","",IF(L34<=C34,0,IF(L34<=C34*(1+BudgetWarnPct),1,2))) | P34: =IF(B34="","",IF(MAX(C34,L34)>0,MAX(C34,L34)+ROW()/100000,""))
E35: =IF(B35="","",IFERROR(1/SUMPRODUCT(MAX((QBlockCat=B35)*QBlockInv)),"")) | F35: =IF(B35="","",SUMIFS('Contractors'!$I$6:$I$1005,'Contractors'!$D$6:$D$1005,B35,'Contractors'!$L$6:$L$1005,"Yes")) | G35: =IF(B35="","",SUMIFS('Selections & Orders'!$L$8:$L$1007,'Selections & Orders'!$D$8:$D$1007,B35)) | H35: =IF(B35="","",SUMIFS('Change Orders'!$J$7:$J$1006,'Change Orders'!$F$7:$F$1006,B35,'Change Orders'!$L$7:$L$1006,"Approved")) | I35: =IF(B35="","",F35+G35+H35) | J35: =IF(B35="","",SUMIFS('Payments'!$L$6:$L$1005,'Payments'!$P$6:$P$1005,B35)) | K35: =IF(B35="","",SUMIFS('Payments'!$N$6:$N$1005,'Payments'!$P$6:$P$1005,B35)) | L35: =IF(B35="","",IF(OR(D35="Estimating",D35=""),MAX(C35,E35,I35,J35),MAX(I35,J35))) | M35: =IF(B35="","",C35-L35) | N35: =IF(O35="","",IF(O35=0,"🟢 On track",IF(O35=1,"🟡 Watch","🔴 Over"))) | O35: =IF(B35="","",IF(L35<=C35,0,IF(L35<=C35*(1+BudgetWarnPct),1,2))) | P35: =IF(B35="","",IF(MAX(C35,L35)>0,MAX(C35,L35)+ROW()/100000,""))
E36: =IF(B36="","",IFERROR(1/SUMPRODUCT(MAX((QBlockCat=B36)*QBlockInv)),"")) | F36: =IF(B36="","",SUMIFS('Contractors'!$I$6:$I$1005,'Contractors'!$D$6:$D$1005,B36,'Contractors'!$L$6:$L$1005,"Yes")) | G36: =IF(B36="","",SUMIFS('Selections & Orders'!$L$8:$L$1007,'Selections & Orders'!$D$8:$D$1007,B36)) | H36: =IF(B36="","",SUMIFS('Change Orders'!$J$7:$J$1006,'Change Orders'!$F$7:$F$1006,B36,'Change Orders'!$L$7:$L$1006,"Approved")) | I36: =IF(B36="","",F36+G36+H36) | J36: =IF(B36="","",SUMIFS('Payments'!$L$6:$L$1005,'Payments'!$P$6:$P$1005,B36)) | K36: =IF(B36="","",SUMIFS('Payments'!$N$6:$N$1005,'Payments'!$P$6:$P$1005,B36)) | L36: =IF(B36="","",IF(OR(D36="Estimating",D36=""),MAX(C36,E36,I36,J36),MAX(I36,J36))) | M36: =IF(B36="","",C36-L36) | N36: =IF(O36="","",IF(O36=0,"🟢 On track",IF(O36=1,"🟡 Watch","🔴 Over"))) | O36: =IF(B36="","",IF(L36<=C36,0,IF(L36<=C36*(1+BudgetWarnPct),1,2))) | P36: =IF(B36="","",IF(MAX(C36,L36)>0,MAX(C36,L36)+ROW()/100000,""))
E37: =IF(B37="","",IFERROR(1/SUMPRODUCT(MAX((QBlockCat=B37)*QBlockInv)),"")) | F37: =IF(B37="","",SUMIFS('Contractors'!$I$6:$I$1005,'Contractors'!$D$6:$D$1005,B37,'Contractors'!$L$6:$L$1005,"Yes")) | G37: =IF(B37="","",SUMIFS('Selections & Orders'!$L$8:$L$1007,'Selections & Orders'!$D$8:$D$1007,B37)) | H37: =IF(B37="","",SUMIFS('Change Orders'!$J$7:$J$1006,'Change Orders'!$F$7:$F$1006,B37,'Change Orders'!$L$7:$L$1006,"Approved")) | I37: =IF(B37="","",F37+G37+H37) | J37: =IF(B37="","",SUMIFS('Payments'!$L$6:$L$1005,'Payments'!$P$6:$P$1005,B37)) | K37: =IF(B37="","",SUMIFS('Payments'!$N$6:$N$1005,'Payments'!$P$6:$P$1005,B37)) | L37: =IF(B37="","",IF(OR(D37="Estimating",D37=""),MAX(C37,E37,I37,J37),MAX(I37,J37))) | M37: =IF(B37="","",C37-L37) | N37: =IF(O37="","",IF(O37=0,"🟢 On track",IF(O37=1,"🟡 Watch","🔴 Over"))) | O37: =IF(B37="","",IF(L37<=C37,0,IF(L37<=C37*(1+BudgetWarnPct),1,2))) | P37: =IF(B37="","",IF(MAX(C37,L37)>0,MAX(C37,L37)+ROW()/100000,""))
... E57: =IF(B57="","",IFERROR(1/SUMPRODUCT(MAX((QBlockCat=B57)*QBlockInv)),"")) | F57: =IF(B57="","",SUMIFS('Contractors'!$I$6:$I$1005,'Contractors'!$D$6:$D$1005,B57,'Contractors'!$L$6:$L$1005,"Yes")) | G57: =IF(B57="","",SUMIFS('Selections & Orders'!$L$8:$L$1007,'Selections & Orders'!$D$8:$D$1007,B57)) | H57: =IF(B57="","",SUMIFS('Change Orders'!$J$7:$J$1006,'Change Orders'!$F$7:$F$1006,B57,'Change Orders'!$L$7:$L$1006,"Approved")) | I57: =IF(B57="","",F57+G57+H57) | J57: =IF(B57="","",SUMIFS('Payments'!$L$6:$L$1005,'Payments'!$P$6:$P$1005,B57)) | K57: =IF(B57="","",SUMIFS('Payments'!$N$6:$N$1005,'Payments'!$P$6:$P$1005,B57)) | L57: =IF(B57="","",IF(OR(D57="Estimating",D57=""),MAX(C57,E57,I57,J57),MAX(I57,J57))) | M57: =IF(B57="","",C57-L57) | N57: =IF(O57="","",IF(O57=0,"🟢 On track",IF(O57=1,"🟡 Watch","🔴 Over"))) | O57: =IF(B57="","",IF(L57<=C57,0,IF(L57<=C57*(1+BudgetWarnPct),1,2))) | P57: =IF(B57="","",IF(MAX(C57,L57)>0,MAX(C57,L57)+ROW()/100000,""))
B58: TOTAL | C58: =SUM(C8:C57) | F58: =SUM(F8:F57) | G58: =SUM(G8:G57) | H58: =SUM(H8:H57) | I58: =SUM(I8:I57) | J58: =SUM(J8:J57) | K58: =SUM(K8:K57) | L58: =SUM(L8:L57) | M58: =SUM(M8:M57) | N58: =IF(O58=0,"🟢 On track",IF(O58=1,"🟡 Watch","🔴 Over")) | O58: =IF(L58<=C58,0,IF(L58<=C58*(1+BudgetWarnPct),1,2))
B59: RISK — what could still come on top of the forecast
B60: Pending change orders (not approved yet) | L60: =SUMIFS('Change Orders'!$J$7:$J$1006,'Change Orders'!$L$7:$L$1006,"Pending") | Q60: =IF(AND(WorkBudget>0,ForecastTotal>WorkBudget),AsOf,"") | R60: =IF(Q60="","",1) | S60: =IF(R60="","","Forecast is over your working budget by "&CurSym&" "&FIXED(ForecastTotal-WorkBudget,0)&" — review Budget")
B61: Estimated cost of open issues | L61: =SUM('Issues & Punch List'!$T$8:$T$1007) | Q61: =IF(ContUsed>0.75,AsOf,"") | R61: =IF(Q61="","",1) | S61: =IF(R61="","","Contingency "&ROUND(ContUsed*100,0)&"% used — pause optional changes")
B62: RISK (could still be added) | L62: =L60+L61
B63: FORECAST INCL. RISK | L63: =ForecastTotal+L62
B64: Contingency used by forecast | L64: =IF(ContAmt>0,MAX(0,ForecastTotal-WorkBudget)/ContAmt,0) | M64: =REPT("█",ROUND(MIN(1,ContUsed)*10,0))&REPT("░",10-ROUND(MIN(1,ContUsed)*10,0))

Sheet Quotes
B1: ⚖️ Quotes
B2: What this tab does: compares up to 4 contractors per trade side by side and reveals the TRUE cost once hidden extras are added.
B3: © 2026 Hang Nguyen — Renovation OS. Licensed to the original purchaser for personal use only. Do not share, copy, resell or redistribute.
B4: SCORING WEIGHTS (points, should total 100)
C5: Price | D5: Timeline | E5: Warranty | F5: Checklist | G5: Gut & refs | H5: Total
B6: Cheapest TRUE cost, shortest timeline and longest warranty get full points; others get proportional points. | C6: 40 | D6: 20 | E6: 15 | F6: 15 | G6: 10 | H6: =SUM(C6:G6)
B7: Tip: type prices exactly as quoted. Yellow checklist cells: estimate what a missing item will cost you — it is added to the TRUE COST.
M8: block cat | N8: best true | O8: 1/best | P8: warn | T8: expiry due | U8: pri | V8: text
B9: COMPARISON 1 ▸ trade: | C9: Kitchen | E9: =IF(COUNT($C$43:$J$43)=0,"Enter up to 4 quotes below","🏆 Best overall: "&INDEX($C$11:$J$11,MATCH(MAX($C$43:$J$43),$C$43:$J$43,0))&" — true cost "&CurSym&" "&FIXED(INDEX($C$35:$J$35,MATCH(MAX($C$43:$J$43),$C$43:$J$43,0)),0)) | M9: =IF(C9="","",C9) | N9: =IF(OR(M9="",COUNT($C35:$J35)=0),"",MIN($C35:$J35)) | O9: =IF(N9="",0,IF(N9>0,1/N9,0)) | T9: =IF(OR(C11="",C19=""),"",IF(OR(IFERROR(INDEX('Budget'!$D$8:$D$57,MATCH($C$9,'Budget'!$B$8:$B$57,0)),"")="Contracted",IFERROR(INDEX('Budget'!$D$8:$D$57,MATCH($C$9,'Budget'!$B$8:$B$57,0)),"")="Complete"),"",IF(C19<AsOf,"",C19))) | U9: =IF(T9="","",IF(T9<AsOf,1,IF(T9<=AsOf+AlertDays,2,IF(T9<=AsOf+2*AlertDays,3,"")))) | V9: =IF(U9="","","Quote expires: "&C11&IF($C$9="",""," ("&$C$9&")")&" — decide or ask for an extension")
C10: Contractor 1 | E10: Contractor 2 | G10: Contractor 3 | I10: Contractor 4 | M10: =IF(C48="","",C48) | N10: =IF(OR(M10="",COUNT($C74:$J74)=0),"",MIN($C74:$J74)) | O10: =IF(N10="",0,IF(N10>0,1/N10,0)) | T10: =IF(OR(E11="",E19=""),"",IF(OR(IFERROR(INDEX('Budget'!$D$8:$D$57,MATCH($C$9,'Budget'!$B$8:$B$57,0)),"")="Contracted",IFERROR(INDEX('Budget'!$D$8:$D$57,MATCH($C$9,'Budget'!$B$8:$B$57,0)),"")="Complete"),"",IF(E19<AsOf,"",E19))) | U10: =IF(T10="","",IF(T10<AsOf,1,IF(T10<=AsOf+AlertDays,2,IF(T10<=AsOf+2*AlertDays,3,"")))) | V10: =IF(U10="","","Quote expires: "&E11&IF($C$9="",""," ("&$C$9&")")&" — decide or ask for an extension")
B11: Contractor / company | C11: BudgetKitchen Co | E11: Nordic Kitchens | G11: Kitchen World | M11: =IF(C87="","",C87) | N11: =IF(OR(M11="",COUNT($C113:$J113)=0),"",MIN($C113:$J113)) | O11: =IF(N11="",0,IF(N11>0,1/N11,0)) | T11: =IF(OR(G11="",G19=""),"",IF(OR(IFERROR(INDEX('Budget'!$D$8:$D$57,MATCH($C$9,'Budget'!$B$8:$B$57,0)),"")="Contracted",IFERROR(INDEX('Budget'!$D$8:$D$57,MATCH($C$9,'Budget'!$B$8:$B$57,0)),"")="Complete"),"",IF(G19<AsOf,"",G19))) | U11: =IF(T11="","",IF(T11<AsOf,1,IF(T11<=AsOf+AlertDays,2,IF(T11<=AsOf+2*AlertDays,3,"")))) | V11: =IF(U11="","","Quote expires: "&G11&IF($C$9="",""," ("&$C$9&")")&" — decide or ask for an extension")
B12: ="Quoted price ("&CurSym&")" | C12: 16900 | E12: 19400 | G12: 18200 | M12: =IF(C126="","",C126) | N12: =IF(OR(M12="",COUNT($C152:$J152)=0),"",MIN($C152:$J152)) | O12: =IF(N12="",0,IF(N12>0,1/N12,0)) | T12: =IF(OR(I11="",I19=""),"",IF(OR(IFERROR(INDEX('Budget'!$D$8:$D$57,MATCH($C$9,'Budget'!$B$8:$B$57,0)),"")="Contracted",IFERROR(INDEX('Budget'!$D$8:$D$57,MATCH($C$9,'Budget'!$B$8:$B$57,0)),"")="Complete"),"",IF(I19<AsOf,"",I19))) | U12: =IF(T12="","",IF(T12<AsOf,1,IF(T12<=AsOf+AlertDays,2,IF(T12<=AsOf+2*AlertDays,3,"")))) | V12: =IF(U12="","","Quote expires: "&I11&IF($C$9="",""," ("&$C$9&")")&" — decide or ask for an extension")
B13: ="Price includes "&TaxWord&"?" | C13: Yes | E13: Yes | G13: No | I13: =DefInclTax | M13: =IF(C165="","",C165) | N13: =IF(OR(M13="",COUNT($C191:$J191)=0),"",MIN($C191:$J191)) | O13: =IF(N13="",0,IF(N13>0,1/N13,0)) | T13: =IF(OR(C50="",C58=""),"",IF(OR(IFERROR(INDEX('Budget'!$D$8:$D$57,MATCH($C$48,'Budget'!$B$8:$B$57,0)),"")="Contracted",IFERROR(INDEX('Budget'!$D$8:$D$57,MATCH($C$48,'Budget'!$B$8:$B$57,0)),"")="Complete"),"",IF(C58<AsOf,"",C58))) | U13: =IF(T13="","",IF(T13<AsOf,1,IF(T13<=AsOf+AlertDays,2,IF(T13<=AsOf+2*AlertDays,3,"")))) | V13: =IF(U13="","","Quote expires: "&C50&IF($C$48="",""," ("&$C$48&")")&" — decide or ask for an extension")
B14: ="Price incl. "&TaxWord&" ("&CurSym&")" | C14: =IF(C12="","",IF(C13="No",C12*(1+VatRate),C12)) | E14: =IF(E12="","",IF(E13="No",E12*(1+VatRate),E12)) | G14: =IF(G12="","",IF(G13="No",G12*(1+VatRate),G12)) | I14: =IF(I12="","",IF(I13="No",I12*(1+VatRate),I12)) | M14: =IF(C204="","",C204) | N14: =IF(OR(M14="",COUNT($C230:$J230)=0),"",MIN($C230:$J230)) | O14: =IF(N14="",0,IF(N14>0,1/N14,0)) | T14: =IF(OR(E50="",E58=""),"",IF(OR(IFERROR(INDEX('Budget'!$D$8:$D$57,MATCH($C$48,'Budget'!$B$8:$B$57,0)),"")="Contracted",IFERROR(INDEX('Budget'!$D$8:$D$57,MATCH($C$48,'Budget'!$B$8:$B$57,0)),"")="Complete"),"",IF(E58<AsOf,"",E58))) | U14: =IF(T14="","",IF(T14<AsOf,1,IF(T14<=AsOf+AlertDays,2,IF(T14<=AsOf+2*AlertDays,3,"")))) | V14: =IF(U14="","","Quote expires: "&E50&IF($C$48="",""," ("&$C$48&")")&" — decide or ask for an extension")
B15: Timeline (weeks) | C15: 3 | E15: 2 | G15: 4 | M15: =IF(C243="","",C243) | N15: =IF(OR(M15="",COUNT($C269:$J269)=0),"",MIN($C269:$J269)) | O15: =IF(N15="",0,IF(N15>0,1/N15,0)) | T15: =IF(OR(G50="",G58=""),"",IF(OR(IFERROR(INDEX('Budget'!$D$8:$D$57,MATCH($C$48,'Budget'!$B$8:$B$57,0)),"")="Contracted",IFERROR(INDEX('Budget'!$D$8:$D$57,MATCH($C$48,'Budget'!$B$8:$B$57,0)),"")="Complete"),"",IF(G58<AsOf,"",G58))) | U15: =IF(T15="","",IF(T15<AsOf,1,IF(T15<=AsOf+AlertDays,2,IF(T15<=AsOf+2*AlertDays,3,"")))) | V15: =IF(U15="","","Quote expires: "&G50&IF($C$48="",""," ("&$C$48&")")&" — decide or ask for an extension")
B16: Warranty (years) | C16: 2 | E16: 5 | G16: 3 | M16: =IF(C282="","",C282) | N16: =IF(OR(M16="",COUNT($C308:$J308)=0),"",MIN($C308:$J308)) | O16: =IF(N16="",0,IF(N16>0,1/N16,0)) | T16: =IF(OR(I50="",I58=""),"",IF(OR(IFERROR(INDEX('Budget'!$D$8:$D$57,MATCH($C$48,'Budget'!$B$8:$B$57,0)),"")="Contracted",IFERROR(INDEX('Budget'!$D$8:$D$57,MATCH($C$48,'Budget'!$B$8:$B$57,0)),"")="Complete"),"",IF(I58<AsOf,"",I58))) | U16: =IF(T16="","",IF(T16<AsOf,1,IF(T16<=AsOf+AlertDays,2,IF(T16<=AsOf+2*AlertDays,3,"")))) | V16: =IF(U16="","","Quote expires: "&I50&IF($C$48="",""," ("&$C$48&")")&" — decide or ask for an extension")
B17: References checked? | C17: No | E17: Yes | G17: Yes | M17: =IF(C321="","",C321) | N17: =IF(OR(M17="",COUNT($C347:$J347)=0),"",MIN($C347:$J347)) | O17: =IF(N17="",0,IF(N17>0,1/N17,0)) | T17: =IF(OR(C89="",C97=""),"",IF(OR(IFERROR(INDEX('Budget'!$D$8:$D$57,MATCH($C$87,'Budget'!$B$8:$B$57,0)),"")="Contracted",IFERROR(INDEX('Budget'!$D$8:$D$57,MATCH($C$87,'Budget'!$B$8:$B$57,0)),"")="Complete"),"",IF(C97<AsOf,"",C97))) | U17: =IF(T17="","",IF(T17<AsOf,1,IF(T17<=AsOf+AlertDays,2,IF(T17<=AsOf+2*AlertDays,3,"")))) | V17: =IF(U17="","","Quote expires: "&C89&IF($C$87="",""," ("&$C$87&")")&" — decide or ask for an extension")
B18: Gut feeling (1–5) | C18: 2 | E18: 5 | G18: 3 | M18: =IF(C360="","",C360) | N18: =IF(OR(M18="",COUNT($C386:$J386)=0),"",MIN($C386:$J386)) | O18: =IF(N18="",0,IF(N18>0,1/N18,0)) | T18: =IF(OR(E89="",E97=""),"",IF(OR(IFERROR(INDEX('Budget'!$D$8:$D$57,MATCH($C$87,'Budget'!$B$8:$B$57,0)),"")="Contracted",IFERROR(INDEX('Budget'!$D$8:$D$57,MATCH($C$87,'Budget'!$B$8:$B$57,0)),"")="Complete"),"",IF(E97<AsOf,"",E97))) | U18: =IF(T18="","",IF(T18<AsOf,1,IF(T18<=AsOf+AlertDays,2,IF(T18<=AsOf+2*AlertDays,3,"")))) | V18: =IF(U18="","","Quote expires: "&E89&IF($C$87="",""," ("&$C$87&")")&" — decide or ask for an extension")
B19: Quote valid until | C19: 46157 | E19: 46162 | G19: 46172 | T19: =IF(OR(G89="",G97=""),"",IF(OR(IFERROR(INDEX('Budget'!$D$8:$D$57,MATCH($C$87,'Budget'!$B$8:$B$57,0)),"")="Contracted",IFERROR(INDEX('Budget'!$D$8:$D$57,MATCH($C$87,'Budget'!$B$8:$B$57,0)),"")="Complete"),"",IF(G97<AsOf,"",G97))) | U19: =IF(T19="","",IF(T19<AsOf,1,IF(T19<=AsOf+AlertDays,2,IF(T19<=AsOf+2*AlertDays,3,"")))) | V19: =IF(U19="","","Quote expires: "&G89&IF($C$87="",""," ("&$C$87&")")&" — decide or ask for an extension")
